Workbook

Sheet Pool_1
L3: Match 1 | M3: =C25 -> Ronald | N3: =E25 -> Diego | O3: =if(AND(C41 = 0, F41 = 0), "Pending", "") | T3: MATCHES | U3: =T4 -> Diego | V3: =T5 -> Eminence Bruin | W3: =T6 -> Tim the Burgundy Enchanter | X3: =T7 -> Teun | Y3: =T8 -> Teake | Z3: =T9 -> Ronald | AA3: Matches Lost | AB3: Won | AC3: Lost | AD3: Total | AG3: ORDER | AI3: BY MATCHES
L4: Match 2 | M4: =C45 -> Eminence Bruin | N4: =E45 -> Teake | O4: =if(AND(C61 = 0, F61 = 0), "Pending", "") | T4: =H8 -> Diego | V4: =F122 -> -1 | W4: =L102 -> 1 | X4: =R62 -> 1 | Y4: =R122 -> -1 | Z4: =C42 -> 1 | AA4: =SUMIF(U4:Z4, ">0") -> 3 | AB4: =U10 -> 2 | AC4: =AA4 -> 3 | AD4: =AB4-AC4+(0.01*AD14)+(0.001*AD24) -> -1.099 | AE4: =T4 -> Diego | AG4: {=sort(AD4:AE9, 1, FALSE)} -> 1.953 | AH4: Tim the Burgundy Enchanter | AI4: Classify
L5: Match 3 | M5: =C65 -> Tim the Burgundy Enchanter | N5: =E65 -> Teun | O5: =if(AND(C81 = 0, F81 = 0), "Pending", "") | T5: =H9 -> Eminence Bruin | U5: =C122 -> 1 | W5: =R82 -> -1 | X5: =L122 -> 0 | Y5: =F62 -> -1 | Z5: =L82 -> -1 | AA5: =SUMIF(U5:Z5, ">0") -> 1 | AB5: =V10 -> 3 | AC5: =AA5 -> 1 | AD5: =AB5-AC5+(0.01*AD15)+(0.001*AD25) -> 1.887 | AE5: =T5 -> Eminence Bruin | AG5: 1.887 | AH5: Eminence Bruin | AI5: Classify
H6: INPUT | L6: Match 4 | M6: =C85 -> Ronald | N6: =E85 -> Teake | O6: =if(AND(C101 = 0, F101 = 0), "Pending", "") | T6: =H10 -> Tim the Burgundy Enchanter | U6: =I102 -> -1 | V6: =O82 -> 1 | X6: =F82 -> 0 | Y6: =R42 -> -1 | Z6: =I42 -> -1 | AA6: =SUMIF(U6:Z6, ">0") -> 1 | AB6: =W10 -> 3 | AC6: =AA6 -> 1 | AD6: =AB6-AC6+(0.01*AD16)+(0.001*AD26) -> 1.953 | AE6: =T6 -> Tim the Burgundy Enchanter | AG6: 0.942 | AH6: Teun | AI6: TBC
L7: Match 5 | M7: =C105 -> Diego | N7: =E105 -> Eminence Bruin | O7: =if(AND(C121 = 0, F121 = 0), "Pending", "") | T7: =H11 -> Teun | U7: =O62 -> -1 | V7: =I122 -> 0 | W7: =C82 -> 0 | Y7: =L62 -> -1 | Z7: =R102 -> 1 | AA7: =SUMIF(U7:Z7, ">0") -> 1 | AB7: =X10 -> 2 | AC7: =AA7 -> 1 | AD7: =AB7-AC7+(0.01*AD17)+(0.001*AD27) -> 0.942 | AE7: =T7 -> Teun | AG7: 0.901 | AH7: Ronald
H8: Diego | L8: Match 6 | M8: =I25 -> Ronald | N8: =K25 -> Tim the Burgundy Enchanter | O8: =if(AND(I41 = 0, L41 = 0), "Pending", "") | T8: =H12 -> Teake | U8: =O122 -> 1 | V8: =C62 -> 1 | W8: =O42 -> 1 | X8: =I62 -> 1 | Z8: =C102 -> 1 | AA8: =SUMIF(U8:Z8, ">0") -> 5 | AB8: =Y10 -> 0 | AC8: =AA8 -> 5 | AD8: =AB8-AC8+(0.01*AD18)+(0.001*AD28) -> -5.124 | AE8: =T8 -> Teake | AG8: -1.099 | AH8: Diego
H9: Eminence Bruin | L9: Match 7 | M9: =I45 -> Teun | N9: =K45 -> Teake | O9: =if(AND(I61 = 0, L61 = 0), "Pending", "") | T9: =H13 -> Ronald | U9: =F42 -> -1 | V9: =I82 -> 1 | W9: =L42 -> 1 | X9: =O102 -> -1 | Y9: =F102 -> -1 | AA9: =SUMIF(U9:Z9, ">0") -> 2 | AB9: =Z10 -> 3 | AC9: =AA9 -> 2 | AD9: =AB9-AC9+(0.01*AD19)+(0.001*AD29) -> 0.901 | AE9: =T9 -> Ronald | AG9: -5.124 | AH9: Teake
H10: Tim the Burgundy Enchanter | L10: Match 8 | M10: =I65 -> Eminence Bruin | N10: =K65 -> Ronald | O10: =if(AND(I81 = 0, L81 = 0), "Pending", "") | T10: Matches Won | U10: =SUMIF(U4:U9, ">0" ,U4:U9) -> 2 | V10: =SUMIF(V4:V9, ">0" ,V4:V9) -> 3 | W10: =SUMIF(W4:W9, ">0" ,W4:W9) -> 3 | X10: =SUMIF(X4:X9, ">0" ,X4:X9) -> 2 | Y10: =SUMIF(Y4:Y9, ">0" ,Y4:Y9) -> 0 | Z10: =SUMIF(Z4:Z9, ">0" ,Z4:Z9) -> 3
H11: Teun | L11: Match 9 | M11: =I85 -> Diego | N11: =K85 -> Tim the Burgundy Enchanter | O11: =if(AND(I101 = 0, L101 = 0), "Pending", "") | U11: =U3 -> Diego | V11: =V3 -> Eminence Bruin | W11: =W3 -> Tim the Burgundy Enchanter | X11: =X3 -> Teun | Y11: =Y3 -> Teake | Z11: =Z3 -> Ronald
H12: Teake | L12: Match 10 | M12: =I105 -> Eminence Bruin | N12: =K105 -> Teun | O12: =if(AND(I121 = 0, L121 = 0), "Pending", "")
H13: Ronald | L13: Match 11 | M13: =O25 -> Tim the Burgundy Enchanter | N13: =Q25 -> Teake | O13: =if(AND(O41 = 0, R41 = 0), "Pending", "") | T13: Doubles | U13: =T14 -> Diego | V13: =T15 -> Eminence Bruin | W13: =T16 -> Tim the Burgundy Enchanter | X13: =T17 -> Teun | Y13: =T18 -> Teake | Z13: =T19 -> Ronald | AA13: Doubles | AD13: Total | AG13: ORDER | AI13: BY POINTS
L14: Match 12 | M14: =O45 -> Diego | N14: =Q45 -> Teun | O14: =if(AND(O61 = 0, R61 = 0), "Pending", "") | T14: =H8 -> Diego | V14: =E121 -> 2 | W14: =K101 -> 3 | X14: =Q61 -> 1 | Y14: =Q121 -> 2 | Z14: =D41 -> 3 | AA14: =SUMIF(U14:Z14, ">0") -> 11 | AD14: =-AA14 -> -11 | AE14: =T14 -> Diego | AG14: {=SORT(AD14:AE19, 1, FALSE)} -> -7 | AH14: Tim the Burgundy Enchanter | AI14: Classify
L15: Match 13 | M15: =O65 -> Eminence Bruin | N15: =Q65 -> Tim the Burgundy Enchanter | O15: =if(AND(O81 = 0, R81 = 0), "Pending", "") | T15: =H9 -> Eminence Bruin | U15: =D121 -> 2 | W15: =Q81 -> 3 | X15: =K121 -> 3 | Y15: =E61 -> 1 | Z15: =K81 -> 3 | AA15: =SUMIF(U15:Z15, ">0") -> 12 | AD15: =-AA15 -> -12 | AE15: =T15 -> Eminence Bruin | AG15: -7 | AH15: Teun | AI15: Classify
L16: Match 14 | M16: =O85 -> Teun | N16: =Q85 -> Ronald | O16: =if(AND(O101 = 0, R101 = 0), "Pending", "") | T16: =H10 -> Tim the Burgundy Enchanter | U16: =J101 -> 3 | V16: =P81 -> 3 | X16: =E81 -> 1 | Y16: =Q41 -> 0 | Z16: =J41 -> 0 | AA16: =SUMIF(U16:Z16, ">0") -> 7 | AD16: =-AA16 -> -7 | AE16: =T16 -> Tim the Burgundy Enchanter | AG16: -7 | AH16: Teake | AI16: TBC
L17: Match 15 | M17: =O105 -> Diego | N17: =Q105 -> Teake | O17: =if(AND(O121 = 0, R121 = 0), "Pending", "") | T17: =H11 -> Teun | U17: =P61 -> 1 | V17: =J121 -> 3 | W17: =D81 -> 1 | Y17: =K61 -> 1 | Z17: =Q101 -> 1 | AA17: =SUMIF(U17:Z17, ">0") -> 7 | AD17: =-AA17 -> -7 | AE17: =T17 -> Teun | AG17: -10 | AH17: Ronald
T18: =H12 -> Teake | U18: =P121 -> 2 | V18: =D61 -> 1 | W18: =P41 -> 0 | X18: =J61 -> 1 | Z18: =D101 -> 3 | AA18: =SUMIF(U18:Z18, ">0") -> 7 | AD18: =-AA18 -> -7 | AE18: =T18 -> Teake | AG18: -11 | AH18: Diego
T19: =H13 -> Ronald | U19: =E41 -> 3 | V19: =J81 -> 3 | W19: =K41 -> 0 | X19: =P101 -> 1 | Y19: =E101 -> 3 | AA19: =SUMIF(U19:Z19, ">0") -> 10 | AD19: =-AA19 -> -10 | AE19: =T19 -> Ronald | AG19: -12 | AH19: Eminence Bruin
T20: Doubles | U20: =SUM(U14:U19) -> 11 | V20: =SUM(V14:V19) -> 12 | W20: =SUM(W14:W19) -> 7 | X20: =SUM(X14:X19) -> 7 | Y20: =SUM(Y14:Y19) -> 7 | Z20: =SUM(Z14:Z19) -> 10
U21: =U13 -> Diego | V21: =V13 -> Eminence Bruin | W21: =W13 -> Tim the Burgundy Enchanter | X21: =X13 -> Teun | Y21: =Y13 -> Teake | Z21: =Z13 -> Ronald
AD22: 50
D23: INPUT | J23: INPUT | P23: INPUT | T23: POINTS | U23: =T24 -> Diego | V23: =T25 -> Eminence Bruin | W23: =T26 -> Tim the Burgundy Enchanter | X23: =T27 -> Teun | Y23: =T28 -> Teake | Z23: =T29 -> Ronald | AA23: Points Lost | AB23: Won | AC23: Lost | AD23: Total | AG23: ORDER | AI23: BY POINTS
T24: =H8 -> Diego | V24: =F121 -> 6 | W24: =L101 -> 7 | X24: =R61 -> 12 | Y24: =R121 -> 2 | Z24: =C41 -> 9 | AA24: =SUMIF(U24:Z24, ">0") -> 36 | AB24: =U30 -> 47 | AC24: =AA24 -> 36 | AD24: =AB24-AC24 -> 11 | AE24: =T24 -> Diego | AG24: {=SORT(AD24:AE29, 1, FALSE)} -> 23 | AH24: Tim the Burgundy Enchanter | AI24: Classify
B25: Match 1 | C25: =T29 -> Ronald | E25: =T24 -> Diego | H25: Match 6 | I25: =T29 -> Ronald | K25: =T26 -> Tim the Burgundy Enchanter | N25: Match 11 | O25: =T26 -> Tim the Burgundy Enchanter | Q25: =T28 -> Teake | T25: =H9 -> Eminence Bruin | U25: =C121 -> 10 | W25: =R81 -> 6 | X25: =L121 -> 7 | Y25: =F61 -> 4 | Z25: =L81 -> 8 | AA25: =SUMIF(U25:Z25, ">0") -> 35 | AB25: =V30 -> 42 | AC25: =AA25 -> 35 | AD25: =AB25-AC25 -> 7 | AE25: =T25 -> Eminence Bruin | AG25: 12 | AH25: Teun | AI25: Classify
B26: Exchange 1 | C26: =IF(AND(D26>0,E26>0), 0, D26) | E26: 2 | F26: =IF(AND(D26>0,E26>0), 0, E26) -> 2 | H26: Exchange 1 | I26: =IF(AND(J26>0,K26>0), 0, J26) | K26: 2 | L26: =IF(AND(J26>0,K26>0), 0, K26) -> 2 | N26: Exchange 1 | O26: =IF(AND(P26>0,Q26>0), 0, P26) -> 2 | P26: 2 | R26: =IF(AND(P26>0,Q26>0), 0, Q26) | T26: =H10 -> Tim the Burgundy Enchanter | U26: =I101 -> 3 | V26: =O81 -> 9 | X26: =F81 -> 12 | Y26: =R41 -> 5 | Z26: =I41 -> 8 | AA26: =SUMIF(U26:Z26, ">0") -> 37 | AB26: =W30 -> 60 | AC26: =AA26 -> 37 | AD26: =AB26-AC26 -> 23 | AE26: =T26 -> Tim the Burgundy Enchanter | AG26: 11 | AH26: Diego | AI26: TBC
B27: Exchange 2 | C27: =IF(AND(D27>0,E27>0), 0, D27) -> 1 | D27: 1 | F27: =IF(AND(D27>0,E27>0), 0, E27) | H27: Exchange 2 | I27: =IF(AND(J27>0,K27>0), 0, J27) -> 2 | J27: 2 | L27: =IF(AND(J27>0,K27>0), 0, K27) | N27: Exchange 2 | O27: =IF(AND(P27>0,Q27>0), 0, P27) -> 2 | P27: 2 | R27: =IF(AND(P27>0,Q27>0), 0, Q27) | T27: =H11 -> Teun | U27: =O61 -> 4 | V27: =I121 -> 7 | W27: =C81 -> 12 | Y27: =L61 -> 3 | Z27: =R101 -> 10 | AA27: =SUMIF(U27:Z27, ">0") -> 36 | AB27: =X30 -> 48 | AC27: =AA27 -> 36 | AD27: =AB27-AC27 -> 12 | AE27: =T27 -> Teun | AG27: 7 | AH27: Eminence Bruin
B28: Exchange 3 | C28: =IF(AND(D28>0,E28>0), 0, D28) -> 0 | D28: 2 | E28: 3 | F28: =IF(AND(D28>0,E28>0), 0, E28) -> 0 | H28: Exchange 3 | I28: =IF(AND(J28>0,K28>0), 0, J28) -> 3 | J28: 3 | L28: =IF(AND(J28>0,K28>0), 0, K28) | N28: Exchange 3 | O28: =IF(AND(P28>0,Q28>0), 0, P28) | Q28: 3 | R28: =IF(AND(P28>0,Q28>0), 0, Q28) -> 3 | T28: =H12 -> Teake | U28: =O121 -> 22 | V28: =C61 -> 11 | W28: =O41 -> 18 | X28: =I61 -> 11 | Z28: =C101 -> 11 | AA28: =SUMIF(U28:Z28, ">0") -> 73 | AB28: =Y30 -> 19 | AC28: =AA28 -> 73 | AD28: =AB28-AC28 -> -54 | AE28: =T28 -> Teake | AG28: 1 | AH28: Ronald
B29: Exchange 4 | C29: =IF(AND(D29>0,E29>0), 0, D29) | E29: 2 | F29: =IF(AND(D29>0,E29>0), 0, E29) -> 2 | H29: Exchange 4 | I29: =IF(AND(J29>0,K29>0), 0, J29) | K29: 3 | L29: =IF(AND(J29>0,K29>0), 0, K29) -> 3 | N29: Exchange 4 | O29: =IF(AND(P29>0,Q29>0), 0, P29) -> 2 | P29: 2 | R29: =IF(AND(P29>0,Q29>0), 0, Q29) | T29: =H13 -> Ronald | U29: =F41 -> 8 | V29: =I81 -> 9 | W29: =L41 -> 17 | X29: =O101 -> 6 | Y29: =F101 -> 5 | AA29: =SUMIF(U29:Z29, ">0") -> 45 | AB29: =Z30 -> 46 | AC29: =AA29 -> 45 | AD29: =AB29-AC29 -> 1 | AE29: =T29 -> Ronald | AG29: -54 | AH29: Teake
B30: Exchange 5 | C30: =IF(AND(D30>0,E30>0), 0, D30) | E30: 2 | F30: =IF(AND(D30>0,E30>0), 0, E30) -> 2 | H30: Exchange 5 | I30: =IF(AND(J30>0,K30>0), 0, J30) | K30: 2 | L30: =IF(AND(J30>0,K30>0), 0, K30) -> 2 | N30: Exchange 5 | O30: =IF(AND(P30>0,Q30>0), 0, P30) | Q30: 2 | R30: =IF(AND(P30>0,Q30>0), 0, Q30) -> 2 | T30: Points Won | U30: =SUM(U24:U29) -> 47 | V30: =SUM(V24:V29) -> 42 | W30: =SUM(W24:W29) -> 60 | X30: =SUM(X24:X29) -> 48 | Y30: =SUM(Y24:Y29) -> 19 | Z30: =SUM(Z24:Z29) -> 46
B31: Exchange 6 | C31: =IF(AND(D31>0,E31>0), 0, D31) -> 0 | D31: 2 | E31: 2 | F31: =IF(AND(D31>0,E31>0), 0, E31) -> 0 | H31: Exchange 6 | I31: =IF(AND(J31>0,K31>0), 0, J31) | K31: 2 | L31: =IF(AND(J31>0,K31>0), 0, K31) -> 2 | N31: Exchange 6 | O31: =IF(AND(P31>0,Q31>0), 0, P31) -> 2 | P31: 2 | R31: =IF(AND(P31>0,Q31>0), 0, Q31) | U31: =U23 -> Diego | V31: =V23 -> Eminence Bruin | W31: =W23 -> Tim the Burgundy Enchanter | X31: =X23 -> Teun | Y31: =Y23 -> Teake | Z31: =Z23 -> Ronald
B32: Exchange 7 | C32: =IF(AND(D32>0,E32>0), 0, D32) -> 3 | D32: 3 | F32: =IF(AND(D32>0,E32>0), 0, E32) | H32: Exchange 7 | I32: =IF(AND(J32>0,K32>0), 0, J32) | K32: 2 | L32: =IF(AND(J32>0,K32>0), 0, K32) -> 2 | N32: Exchange 7 | O32: =IF(AND(P32>0,Q32>0), 0, P32) -> 2 | P32: 2 | R32: =IF(AND(P32>0,Q32>0), 0, Q32) | AD32: 100
B33: Exchange 8 | C33: =IF(AND(D33>0,E33>0), 0, D33) | E33: 2 | F33: =IF(AND(D33>0,E33>0), 0, E33) -> 2 | H33: Exchange 8 | I33: =IF(AND(J33>0,K33>0), 0, J33) | K33: 2 | L33: =IF(AND(J33>0,K33>0), 0, K33) -> 2 | N33: Exchange 8 | O33: =IF(AND(P33>0,Q33>0), 0, P33) -> 2 | P33: 2 | R33: =IF(AND(P33>0,Q33>0), 0, Q33)
B34: Exchange 9 | C34: =IF(AND(D34>0,E34>0), 0, D34) -> 0 | D34: 2 | E34: 2 | F34: =IF(AND(D34>0,E34>0), 0, E34) -> 0 | H34: Exchange 9 | I34: =IF(AND(J34>0,K34>0), 0, J34) | K34: 2 | L34: =IF(AND(J34>0,K34>0), 0, K34) -> 2 | N34: Exchange 9 | O34: =IF(AND(P34>0,Q34>0), 0, P34) -> 3 | P34: 3 | R34: =IF(AND(P34>0,Q34>0), 0, Q34)
B35: Exchange 10 | C35: =IF(AND(D35>0,E35>0), 0, D35) -> 3 | D35: 3 | F35: =IF(AND(D35>0,E35>0), 0, E35) | H35: Exchange 10 | I35: =IF(AND(J35>0,K35>0), 0, J35) | K35: 2 | L35: =IF(AND(J35>0,K35>0), 0, K35) -> 2 | N35: Exchange 10 | O35: =IF(AND(P35>0,Q35>0), 0, P35) -> 3 | P35: 3 | R35: =IF(AND(P35>0,Q35>0), 0, Q35)
B36: Exchange 11 | C36: =IF(AND(D36>0,E36>0), 0, D36) -> 2 | D36: 2 | F36: =IF(AND(D36>0,E36>0), 0, E36) | H36: Exchange 11 | I36: =IF(AND(J36>0,K36>0), 0, J36) -> 3 | J36: 3 | L36: =IF(AND(J36>0,K36>0), 0, K36) | N36: Exchange 11 | O36: =IF(AND(P36>0,Q36>0), 0, P36) | R36: =IF(AND(P36>0,Q36>0), 0, Q36)
B37: Exchange 12 | C37: =IF(AND(D37>0,E37>0), 0, D37) | F37: =IF(AND(D37>0,E37>0), 0, E37) | H37: Exchange 12 | I37: =IF(AND(J37>0,K37>0), 0, J37) | L37: =IF(AND(J37>0,K37>0), 0, K37) | N37: Exchange 12 | O37: =IF(AND(P37>0,Q37>0), 0, P37) | R37: =IF(AND(P37>0,Q37>0), 0, Q37)
B38: Exchange 13 | C38: =IF(AND(D38>0,E38>0), 0, D38) | F38: =IF(AND(D38>0,E38>0), 0, E38) | H38: Exchange 13 | I38: =IF(AND(J38>0,K38>0), 0, J38) | L38: =IF(AND(J38>0,K38>0), 0, K38) | N38: Exchange 13 | O38: =IF(AND(P38>0,Q38>0), 0, P38) | R38: =IF(AND(P38>0,Q38>0), 0, Q38)
B39: Exchange 14 | C39: =IF(AND(D39>0,E39>0), 0, D39) | F39: =IF(AND(D39>0,E39>0), 0, E39) | H39: Exchange 14 | I39: =IF(AND(J39>0,K39>0), 0, J39) | L39: =IF(AND(J39>0,K39>0), 0, K39) | N39: Exchange 14 | O39: =IF(AND(P39>0,Q39>0), 0, P39) | R39: =IF(AND(P39>0,Q39>0), 0, Q39)
B40: Exchange 15 | C40: =IF(AND(D40>0,E40>0), 0, D40) | F40: =IF(AND(D40>0,E40>0), 0, E40) | H40: Exchange 15 | I40: =IF(AND(J40>0,K40>0), 0, J40) | L40: =IF(AND(J40>0,K40>0), 0, K40) | N40: Exchange 15 | O40: =IF(AND(P40>0,Q40>0), 0, P40) | R40: =IF(AND(P40>0,Q40>0), 0, Q40)
B41: Won Points | C41: =SUM(C26:C40) -> 9 | D41: =COUNTIFS(D26:D40, "<>0", D26:D40, "<>", E26:E40, "<>0", E26:E40, "<>") -> 3 | E41: =COUNTIFS(D26:D40, "<>0", D26:D40, "<>", E26:E40, "<>0", E26:E40, "<>") -> 3 | F41: =SUM(F26:F40) -> 8 | H41: Won Points | I41: =SUM(I26:I40) -> 8 | J41: =COUNTIFS(J26:J40, "<>0", J26:J40, "<>", K26:K40, "<>0", K26:K40, "<>") -> 0 | K41: =COUNTIFS(J26:J40, "<>0", J26:J40, "<>", K26:K40, "<>0", K26:K40, "<>") -> 0 | L41: =SUM(L26:L40) -> 17 | N41: Won Points | O41: =SUM(O26:O40) -> 18 | P41: =COUNTIFS(P26:P40, "<>0", P26:P40, "<>", Q26:Q40, "<>0", Q26:Q40, "<>") -> 0 | Q41: =COUNTIFS(P26:P40, "<>0", P26:P40, "<>", Q26:Q40, "<>0", Q26:Q40, "<>") -> 0 | R41: =SUM(R26:R40) -> 5
B42: Won Match | C42: =D42 -> 1 | D42: =IF(C41>F41, 1, (IF(C41=F41, 0, -1))) -> 1 | E42: =IF(F41>C41, 1, (IF(F41=C41, 0, -1))) -> -1 | F42: =E42 -> -1 | H42: Won Match | I42: =J42 -> -1 | J42: =IF(I41>L41, 1, (IF(I41=L41, 0, -1))) -> -1 | K42: =IF(L41>I41, 1, (IF(L41=I41, 0, -1))) -> 1 | L42: =K42 -> 1 | N42: Won Match | O42: =P42 -> 1 | P42: =IF(O41>R41, 1, (IF(O41=R41, 0, -1))) -> 1 | Q42: =IF(R41>O41, 1, (IF(R41=O41, 0, -1))) -> -1 | R42: =Q42 -> -1
...

Sheet Pool_2
L3: Match 1 | M3: =C25 -> Maarten | N3: =E25 -> Arjan | O3: =if(AND(C41 = 0, F41 = 0), "Pending", "") | T3: MATCHES | U3: =T4 -> Arjan | V3: =T5 -> Willem | W3: =T6 -> Eva | X3: =T7 -> Rory | Y3: =T8 -> Jesse | Z3: =T9 -> Maarten | AA3: Matches Lost | AB3: Won | AC3: Lost | AD3: Total | AG3: ORDER | AI3: BY MATCHES
L4: Match 2 | M4: =C45 -> Willem | N4: =E45 -> Jesse | O4: =if(AND(C61 = 0, F61 = 0), "Pending", "") | T4: =H8 -> Arjan | V4: =F122 -> -1 | W4: =L102 -> -1 | X4: =R62 -> 1 | Y4: =R122 -> 1 | Z4: =C42 -> -1 | AA4: =SUMIF(U4:Z4, ">0") -> 2 | AB4: =U10 -> 3 | AC4: =AA4 -> 2 | AD4: =AB4-AC4+(0.01*AD14)+(0.001*AD24) -> 0.868 | AE4: =T4 -> Arjan | AG4: {=sort(AD4:AE9, 1, FALSE)} -> 4.927 | AH4: Jesse | AI4: Classify
L5: Match 3 | M5: =C65 -> Eva | N5: =E65 -> Rory | O5: =if(AND(C81 = 0, F81 = 0), "Pending", "") | T5: =H9 -> Willem | U5: =C122 -> 1 | W5: =R82 -> -1 | X5: =L122 -> 0 | Y5: =F62 -> 1 | Z5: =L82 -> 1 | AA5: =SUMIF(U5:Z5, ">0") -> 3 | AB5: =V10 -> 1 | AC5: =AA5 -> 3 | AD5: =AB5-AC5+(0.01*AD15)+(0.001*AD25) -> -2.108 | AE5: =T5 -> Willem | AG5: 1.893 | AH5: Rory | AI5: Classify
H6: INPUT | L6: Match 4 | M6: =C85 -> Maarten | N6: =E85 -> Jesse | O6: =if(AND(C101 = 0, F101 = 0), "Pending", "") | T6: =H10 -> Eva | U6: =I102 -> 1 | V6: =O82 -> 1 | X6: =F82 -> 1 | Y6: =R42 -> 1 | Z6: =I42 -> 1 | AA6: =SUMIF(U6:Z6, ">0") -> 5 | AB6: =W10 -> 0 | AC6: =AA6 -> 5 | AD6: =AB6-AC6+(0.01*AD16)+(0.001*AD26) -> -5.153 | AE6: =T6 -> Eva | AG6: 0.868 | AH6: Arjan | AI6: TBC
L7: Match 5 | M7: =C105 -> Arjan | N7: =E105 -> Willem | O7: =if(AND(C121 = 0, F121 = 0), "Pending", "") | T7: =H11 -> Rory | U7: =O62 -> -1 | V7: =I122 -> 0 | W7: =C82 -> -1 | Y7: =L62 -> 1 | Z7: =R102 -> -1 | AA7: =SUMIF(U7:Z7, ">0") -> 1 | AB7: =X10 -> 3 | AC7: =AA7 -> 1 | AD7: =AB7-AC7+(0.01*AD17)+(0.001*AD27) -> 1.893 | AE7: =T7 -> Rory | AG7: -1.087 | AH7: Maarten
H8: Arjan | L8: Match 6 | M8: =I25 -> Maarten | N8: =K25 -> Eva | O8: =if(AND(I41 = 0, L41 = 0), "Pending", "") | T8: =H12 -> Jesse | U8: =O122 -> -1 | V8: =C62 -> -1 | W8: =O42 -> -1 | X8: =I62 -> -1 | Z8: =C102 -> -1 | AA8: =SUMIF(U8:Z8, ">0") -> 0 | AB8: =Y10 -> 5 | AC8: =AA8 -> 0 | AD8: =AB8-AC8+(0.01*AD18)+(0.001*AD28) -> 4.927 | AE8: =T8 -> Jesse | AG8: -2.108 | AH8: Willem
H9: Willem | L9: Match 7 | M9: =I45 -> Rory | N9: =K45 -> Jesse | O9: =if(AND(I61 = 0, L61 = 0), "Pending", "") | T9: =H13 -> Maarten | U9: =F42 -> 1 | V9: =I82 -> -1 | W9: =L42 -> -1 | X9: =O102 -> 1 | Y9: =F102 -> 1 | AA9: =SUMIF(U9:Z9, ">0") -> 3 | AB9: =Z10 -> 2 | AC9: =AA9 -> 3 | AD9: =AB9-AC9+(0.01*AD19)+(0.001*AD29) -> -1.087 | AE9: =T9 -> Maarten | AG9: -5.153 | AH9: Eva
H10: Eva | L10: Match 8 | M10: =I65 -> Willem | N10: =K65 -> Maarten | O10: =if(AND(I81 = 0, L81 = 0), "Pending", "") | T10: Matches Won | U10: =SUMIF(U4:U9, ">0" ,U4:U9) -> 3 | V10: =SUMIF(V4:V9, ">0" ,V4:V9) -> 1 | W10: =SUMIF(W4:W9, ">0" ,W4:W9) -> 0 | X10: =SUMIF(X4:X9, ">0" ,X4:X9) -> 3 | Y10: =SUMIF(Y4:Y9, ">0" ,Y4:Y9) -> 5 | Z10: =SUMIF(Z4:Z9, ">0" ,Z4:Z9) -> 2
H11: Rory | L11: Match 9 | M11: =I85 -> Arjan | N11: =K85 -> Eva | O11: =if(AND(I101 = 0, L101 = 0), "Pending", "") | U11: =U3 -> Arjan | V11: =V3 -> Willem | W11: =W3 -> Eva | X11: =X3 -> Rory | Y11: =Y3 -> Jesse | Z11: =Z3 -> Maarten
H12: Jesse | L12: Match 10 | M12: =I105 -> Willem | N12: =K105 -> Rory | O12: =if(AND(I121 = 0, L121 = 0), "Pending", "")
H13: Maarten | L13: Match 11 | M13: =O25 -> Eva | N13: =Q25 -> Jesse | O13: =if(AND(O41 = 0, R41 = 0), "Pending", "") | T13: Doubles | U13: =T14 -> Arjan | V13: =T15 -> Willem | W13: =T16 -> Eva | X13: =T17 -> Rory | Y13: =T18 -> Jesse | Z13: =T19 -> Maarten | AA13: Doubles | AD13: Total | AG13: ORDER | AI13: BY POINTS
L14: Match 12 | M14: =O45 -> Arjan | N14: =Q45 -> Rory | O14: =if(AND(O61 = 0, R61 = 0), "Pending", "") | T14: =H8 -> Arjan | V14: =E121 -> 1 | W14: =K101 -> 4 | X14: =Q61 -> 1 | Y14: =Q121 -> 5 | Z14: =D41 -> 2 | AA14: =SUMIF(U14:Z14, ">0") -> 13 | AD14: =-AA14 -> -13 | AE14: =T14 -> Arjan | AG14: {=SORT(AD14:AE19, 1, FALSE)} -> -8 | AH14: Maarten | AI14: Classify
L15: Match 13 | M15: =O65 -> Willem | N15: =Q65 -> Eva | O15: =if(AND(O81 = 0, R81 = 0), "Pending", "") | T15: =H9 -> Willem | U15: =D121 -> 1 | W15: =Q81 -> 3 | X15: =K121 -> 5 | Y15: =E61 -> 1 | Z15: =K81 -> 1 | AA15: =SUMIF(U15:Z15, ">0") -> 11 | AD15: =-AA15 -> -11 | AE15: =T15 -> Willem | AG15: -9 | AH15: Eva | AI15: Classify
L16: Match 14 | M16: =O85 -> Rory | N16: =Q85 -> Maarten | O16: =if(AND(O101 = 0, R101 = 0), "Pending", "") | T16: =H10 -> Eva | U16: =J101 -> 4 | V16: =P81 -> 3 | X16: =E81 -> 0 | Y16: =Q41 -> 2 | Z16: =J41 -> 0 | AA16: =SUMIF(U16:Z16, ">0") -> 9 | AD16: =-AA16 -> -9 | AE16: =T16 -> Eva | AG16: -11 | AH16: Willem | AI16: TBC
L17: Match 15 | M17: =O105 -> Arjan | N17: =Q105 -> Jesse | O17: =if(AND(O121 = 0, R121 = 0), "Pending", "") | T17: =H11 -> Rory | U17: =P61 -> 1 | V17: =J121 -> 5 | W17: =D81 -> 0 | Y17: =K61 -> 3 | Z17: =Q101 -> 4 | AA17: =SUMIF(U17:Z17, ">0") -> 13 | AD17: =-AA17 -> -13 | AE17: =T17 -> Rory | AG17: -12 | AH17: Jesse
T18: =H12 -> Jesse | U18: =P121 -> 5 | V18: =D61 -> 1 | W18: =P41 -> 2 | X18: =J61 -> 3 | Z18: =D101 -> 1 | AA18: =SUMIF(U18:Z18, ">0") -> 12 | AD18: =-AA18 -> -12 | AE18: =T18 -> Jesse | AG18: -13 | AH18: Arjan
T19: =H13 -> Maarten | U19: =E41 -> 2 | V19: =J81 -> 1 | W19: =K41 -> 0 | X19: =P101 -> 4 | Y19: =E101 -> 1 | AA19: =SUMIF(U19:Z19, ">0") -> 8 | AD19: =-AA19 -> -8 | AE19: =T19 -> Maarten | AG19: -13 | AH19: Rory
T20: Doubles | U20: =SUM(U14:U19) -> 13 | V20: =SUM(V14:V19) -> 11 | W20: =SUM(W14:W19) -> 9 | X20: =SUM(X14:X19) -> 13 | Y20: =SUM(Y14:Y19) -> 12 | Z20: =SUM(Z14:Z19) -> 8
U21: =U13 -> Arjan | V21: =V13 -> Willem | W21: =W13 -> Eva | X21: =X13 -> Rory | Y21: =Y13 -> Jesse | Z21: =Z13 -> Maarten
AD22: 50
D23: INPUT | J23: INPUT | P23: INPUT | T23: POINTS | U23: =T24 -> Arjan | V23: =T25 -> Willem | W23: =T26 -> Eva | X23: =T27 -> Rory | Y23: =T28 -> Jesse | Z23: =T29 -> Maarten | AA23: Points Lost | AB23: Won | AC23: Lost | AD23: Total | AG23: ORDER | AI23: BY POINTS
T24: =H8 -> Arjan | V24: =F121 -> 8 | W24: =L101 -> 0 | X24: =R61 -> 14 | Y24: =R121 -> 12 | Z24: =C41 -> 7 | AA24: =SUMIF(U24:Z24, ">0") -> 41 | AB24: =U30 -> 39 | AC24: =AA24 -> 41 | AD24: =AB24-AC24 -> -2 | AE24: =T24 -> Arjan | AG24: {=SORT(AD24:AE29, 1, FALSE)} -> 47 | AH24: Jesse | AI24: Classify
B25: Match 1 | C25: =T19 -> Maarten | E25: =T14 -> Arjan | H25: Match 6 | I25: =T19 -> Maarten | K25: =T16 -> Eva | N25: Match 11 | O25: =T16 -> Eva | Q25: =T18 -> Jesse | T25: =H9 -> Willem | U25: =C121 -> 11 | W25: =R81 -> 2 | X25: =L121 -> 6 | Y25: =F61 -> 13 | Z25: =L81 -> 12 | AA25: =SUMIF(U25:Z25, ">0") -> 44 | AB25: =V30 -> 46 | AC25: =AA25 -> 44 | AD25: =AB25-AC25 -> 2 | AE25: =T25 -> Willem | AG25: 23 | AH25: Rory | AI25: Classify
B26: Exchange 1 | C26: =IF(AND(D26>0,E26>0), 0, D26) | E26: 2 | F26: =IF(AND(D26>0,E26>0), 0, E26) -> 2 | H26: Exchange 1 | I26: =IF(AND(J26>0,K26>0), 0, J26) | L26: =IF(AND(J26>0,K26>0), 0, K26) | N26: Exchange 1 | O26: =IF(AND(P26>0,Q26>0), 0, P26) -> 0 | P26: 2 | Q26: 2 | R26: =IF(AND(P26>0,Q26>0), 0, Q26) -> 0 | T26: =H10 -> Eva | U26: =I101 -> 11 | V26: =O81 -> 16 | X26: =F81 -> 16 | Y26: =R41 -> 16 | Z26: =I41 -> 14 | AA26: =SUMIF(U26:Z26, ">0") -> 73 | AB26: =W30 -> 10 | AC26: =AA26 -> 73 | AD26: =AB26-AC26 -> -63 | AE26: =T26 -> Eva | AG26: 2 | AH26: Willem | AI26: TBC
B27: Exchange 2 | C27: =IF(AND(D27>0,E27>0), 0, D27) | E27: 3 | F27: =IF(AND(D27>0,E27>0), 0, E27) -> 3 | H27: Exchange 2 | I27: =IF(AND(J27>0,K27>0), 0, J27) -> 3 | J27: 3 | L27: =IF(AND(J27>0,K27>0), 0, K27) | N27: Exchange 2 | O27: =IF(AND(P27>0,Q27>0), 0, P27) | Q27: 3 | R27: =IF(AND(P27>0,Q27>0), 0, Q27) -> 3 | T27: =H11 -> Rory | U27: =O61 -> 6 | V27: =I121 -> 6 | W27: =C81 -> 2 | Y27: =L61 -> 12 | Z27: =R101 -> 4 | AA27: =SUMIF(U27:Z27, ">0") -> 30 | AB27: =X30 -> 53 | AC27: =AA27 -> 30 | AD27: =AB27-AC27 -> 23 | AE27: =T27 -> Rory | AG27: -2 | AH27: Arjan
B28: Exchange 3 | C28: =IF(AND(D28>0,E28>0), 0, D28) | E28: 2 | F28: =IF(AND(D28>0,E28>0), 0, E28) -> 2 | H28: Exchange 3 | I28: =IF(AND(J28>0,K28>0), 0, J28) -> 2 | J28: 2 | L28: =IF(AND(J28>0,K28>0), 0, K28) | N28: Exchange 3 | O28: =IF(AND(P28>0,Q28>0), 0, P28) | Q28: 3 | R28: =IF(AND(P28>0,Q28>0), 0, Q28) -> 3 | T28: =H12 -> Jesse | U28: =O121 -> 2 | V28: =C61 -> 9 | W28: =O41 -> 0 | X28: =I61 -> 4 | Z28: =C101 -> 7 | AA28: =SUMIF(U28:Z28, ">0") -> 22 | AB28: =Y30 -> 69 | AC28: =AA28 -> 22 | AD28: =AB28-AC28 -> 47 | AE28: =T28 -> Jesse | AG28: -7 | AH28: Maarten
B29: Exchange 4 | C29: =IF(AND(D29>0,E29>0), 0, D29) -> 0 | D29: 2 | E29: 2 | F29: =IF(AND(D29>0,E29>0), 0, E29) -> 0 | H29: Exchange 4 | I29: =IF(AND(J29>0,K29>0), 0, J29) | K29: 2 | L29: =IF(AND(J29>0,K29>0), 0, K29) -> 2 | N29: Exchange 4 | O29: =IF(AND(P29>0,Q29>0), 0, P29) | Q29: 2 | R29: =IF(AND(P29>0,Q29>0), 0, Q29) -> 2 | T29: =H13 -> Maarten | U29: =F41 -> 9 | V29: =I81 -> 7 | W29: =L41 -> 6 | X29: =O101 -> 13 | Y29: =F101 -> 16 | AA29: =SUMIF(U29:Z29, ">0") -> 51 | AB29: =Z30 -> 44 | AC29: =AA29 -> 51 | AD29: =AB29-AC29 -> -7 | AE29: =T29 -> Maarten | AG29: -63 | AH29: Eva
B30: Exchange 5 | C30: =IF(AND(D30>0,E30>0), 0, D30) -> 2 | D30: 2 | F30: =IF(AND(D30>0,E30>0), 0, E30) | H30: Exchange 5 | I30: =IF(AND(J30>0,K30>0), 0, J30) | K30: 2 | L30: =IF(AND(J30>0,K30>0), 0, K30) -> 2 | N30: Exchange 5 | O30: =IF(AND(P30>0,Q30>0), 0, P30) | R30: =IF(AND(P30>0,Q30>0), 0, Q30) | T30: Points Won | U30: =SUM(U24:U29) -> 39 | V30: =SUM(V24:V29) -> 46 | W30: =SUM(W24:W29) -> 10 | X30: =SUM(X24:X29) -> 53 | Y30: =SUM(Y24:Y29) -> 69 | Z30: =SUM(Z24:Z29) -> 44
B31: Exchange 6 | C31: =IF(AND(D31>0,E31>0), 0, D31) | E31: 2 | F31: =IF(AND(D31>0,E31>0), 0, E31) -> 2 | H31: Exchange 6 | I31: =IF(AND(J31>0,K31>0), 0, J31) | L31: =IF(AND(J31>0,K31>0), 0, K31) | N31: Exchange 6 | O31: =IF(AND(P31>0,Q31>0), 0, P31) | Q31: 3 | R31: =IF(AND(P31>0,Q31>0), 0, Q31) -> 3 | U31: =U23 -> Arjan | V31: =V23 -> Willem | W31: =W23 -> Eva | X31: =X23 -> Rory | Y31: =Y23 -> Jesse | Z31: =Z23 -> Maarten
B32: Exchange 7 | C32: =IF(AND(D32>0,E32>0), 0, D32) -> 2 | D32: 2 | F32: =IF(AND(D32>0,E32>0), 0, E32) | H32: Exchange 7 | I32: =IF(AND(J32>0,K32>0), 0, J32) -> 3 | J32: 3 | L32: =IF(AND(J32>0,K32>0), 0, K32) | N32: Exchange 7 | O32: =IF(AND(P32>0,Q32>0), 0, P32) | Q32: 3 | R32: =IF(AND(P32>0,Q32>0), 0, Q32) -> 3
B33: Exchange 8 | C33: =IF(AND(D33>0,E33>0), 0, D33) -> 3 | D33: 3 | F33: =IF(AND(D33>0,E33>0), 0, E33) | H33: Exchange 8 | I33: =IF(AND(J33>0,K33>0), 0, J33) | K33: 2 | L33: =IF(AND(J33>0,K33>0), 0, K33) -> 2 | N33: Exchange 8 | O33: =IF(AND(P33>0,Q33>0), 0, P33) | R33: =IF(AND(P33>0,Q33>0), 0, Q33)
B34: Exchange 9 | C34: =IF(AND(D34>0,E34>0), 0, D34) -> 0 | D34: 3 | E34: 2 | F34: =IF(AND(D34>0,E34>0), 0, E34) -> 0 | H34: Exchange 9 | I34: =IF(AND(J34>0,K34>0), 0, J34) -> 3 | J34: 3 | L34: =IF(AND(J34>0,K34>0), 0, K34) | N34: Exchange 9 | O34: =IF(AND(P34>0,Q34>0), 0, P34) | Q34: 2 | R34: =IF(AND(P34>0,Q34>0), 0, Q34) -> 2
B35: Exchange 10 | C35: =IF(AND(D35>0,E35>0), 0, D35) | F35: =IF(AND(D35>0,E35>0), 0, E35) | H35: Exchange 10 | I35: =IF(AND(J35>0,K35>0), 0, J35) -> 3 | J35: 3 | L35: =IF(AND(J35>0,K35>0), 0, K35) | N35: Exchange 10 | O35: =IF(AND(P35>0,Q35>0), 0, P35) -> 0 | P35: 2 | Q35: 3 | R35: =IF(AND(P35>0,Q35>0), 0, Q35) -> 0
B36: Exchange 11 | C36: =IF(AND(D36>0,E36>0), 0, D36) | F36: =IF(AND(D36>0,E36>0), 0, E36) | H36: Exchange 11 | I36: =IF(AND(J36>0,K36>0), 0, J36) | L36: =IF(AND(J36>0,K36>0), 0, K36) | N36: Exchange 11 | O36: =IF(AND(P36>0,Q36>0), 0, P36) | R36: =IF(AND(P36>0,Q36>0), 0, Q36)
B37: Exchange 12 | C37: =IF(AND(D37>0,E37>0), 0, D37) | F37: =IF(AND(D37>0,E37>0), 0, E37) | H37: Exchange 12 | I37: =IF(AND(J37>0,K37>0), 0, J37) | L37: =IF(AND(J37>0,K37>0), 0, K37) | N37: Exchange 12 | O37: =IF(AND(P37>0,Q37>0), 0, P37) | R37: =IF(AND(P37>0,Q37>0), 0, Q37)
B38: Exchange 13 | C38: =IF(AND(D38>0,E38>0), 0, D38) | F38: =IF(AND(D38>0,E38>0), 0, E38) | H38: Exchange 13 | I38: =IF(AND(J38>0,K38>0), 0, J38) | L38: =IF(AND(J38>0,K38>0), 0, K38) | N38: Exchange 13 | O38: =IF(AND(P38>0,Q38>0), 0, P38) | R38: =IF(AND(P38>0,Q38>0), 0, Q38)
B39: Exchange 14 | C39: =IF(AND(D39>0,E39>0), 0, D39) | F39: =IF(AND(D39>0,E39>0), 0, E39) | H39: Exchange 14 | I39: =IF(AND(J39>0,K39>0), 0, J39) | L39: =IF(AND(J39>0,K39>0), 0, K39) | N39: Exchange 14 | O39: =IF(AND(P39>0,Q39>0), 0, P39) | R39: =IF(AND(P39>0,Q39>0), 0, Q39)
B40: Exchange 15 | C40: =IF(AND(D40>0,E40>0), 0, D40) | F40: =IF(AND(D40>0,E40>0), 0, E40) | H40: Exchange 15 | I40: =IF(AND(J40>0,K40>0), 0, J40) | L40: =IF(AND(J40>0,K40>0), 0, K40) | N40: Exchange 15 | O40: =IF(AND(P40>0,Q40>0), 0, P40) | R40: =IF(AND(P40>0,Q40>0), 0, Q40)
B41: Won Points | C41: =SUM(C26:C40) -> 7 | D41: =COUNTIFS(D26:D40, "<>0", D26:D40, "<>", E26:E40, "<>0", E26:E40, "<>") -> 2 | E41: =COUNTIFS(D26:D40, "<>0", D26:D40, "<>", E26:E40, "<>0", E26:E40, "<>") -> 2 | F41: =SUM(F26:F40) -> 9 | H41: Won Points | I41: =SUM(I26:I40) -> 14 | J41: =COUNTIFS(J26:J40, "<>0", J26:J40, "<>", K26:K40, "<>0", K26:K40, "<>") -> 0 | K41: =COUNTIFS(J26:J40, "<>0", J26:J40, "<>", K26:K40, "<>0", K26:K40, "<>") -> 0 | L41: =SUM(L26:L40) -> 6 | N41: Won Points | O41: =SUM(O26:O40) -> 0 | P41: =COUNTIFS(P26:P40, "<>0", P26:P40, "<>", Q26:Q40, "<>0", Q26:Q40, "<>") -> 2 | Q41: =COUNTIFS(P26:P40, "<>0", P26:P40, "<>", Q26:Q40, "<>0", Q26:Q40, "<>") -> 2 | R41: =SUM(R26:R40) -> 16
B42: Won Match | C42: =D42 -> -1 | D42: =IF(C41>F41, 1, (IF(C41=F41, 0, -1))) -> -1 | E42: =IF(F41>C41, 1, (IF(F41=C41, 0, -1))) -> 1 | F42: =E42 -> 1 | H42: Won Match | I42: =J42 -> 1 | J42: =IF(I41>L41, 1, (IF(I41=L41, 0, -1))) -> 1 | K42: =IF(L41>I41, 1, (IF(L41=I41, 0, -1))) -> -1 | L42: =K42 -> -1 | N42: Won Match | O42: =P42 -> -1 | P42: =IF(O41>R41, 1, (IF(O41=R41, 0, -1))) -> -1 | Q42: =IF(R41>O41, 1, (IF(R41=O41, 0, -1))) -> 1 | R42: =Q42 -> 1
...

Sheet Pool_3
L3: Match 1 | M3: =C25 -> Mittens | N3: =E25 -> Berend | O3: =if(AND(C41 = 0, F41 = 0), "Pending", "") | T3: MATCHES | U3: =T4 -> Berend | V3: =T5 -> Judith | W3: =T6 -> Tjeard | X3: =T7 -> Daniel | Y3: =T8 -> Frank | Z3: =T9 -> Mittens | AA3: Matches Lost | AB3: Won | AC3: Lost | AD3: Total | AG3: ORDER | AI3: BY MATCHES
L4: Match 2 | M4: =C45 -> Judith | N4: =E45 -> Frank | O4: =if(AND(C61 = 0, F61 = 0), "Pending", "") | T4: =H8 -> Berend | V4: =F122 -> -1 | W4: =L102 -> 1 | X4: =R62 -> -1 | Y4: =R122 -> -1 | Z4: =C42 -> -1 | AA4: =SUMIF(U4:Z4, ">0") -> 1 | AB4: =U10 -> 4 | AC4: =AA4 -> 1 | AD4: =AB4-AC4+(0.01*AD14)+(0.001*AD24) -> 2.854 | AE4: =T4 -> Berend | AG4: {=sort(AD4:AE9, 1, FALSE)} -> 2.854 | AH4: Berend | AI4: Classify
L5: Match 3 | M5: =C65 -> Tjeard | N5: =E65 -> Daniel | O5: =if(AND(C81 = 0, F81 = 0), "Pending", "") | T5: =H9 -> Judith | U5: =C122 -> 1 | W5: =R82 -> 1 | X5: =L122 -> -1 | Y5: =F62 -> 1 | Z5: =L82 -> -1 | AA5: =SUMIF(U5:Z5, ">0") -> 3 | AB5: =V10 -> 2 | AC5: =AA5 -> 3 | AD5: =AB5-AC5+(0.01*AD15)+(0.001*AD25) -> -1.152 | AE5: =T5 -> Judith | AG5: 2.829 | AH5: Tjeard | AI5: Classify
H6: INPUT | L6: Match 4 | M6: =C85 -> Mittens | N6: =E85 -> Frank | O6: =if(AND(C101 = 0, F101 = 0), "Pending", "") | T6: =H10 -> Tjeard | U6: =I102 -> -1 | V6: =O82 -> -1 | X6: =F82 -> 1 | Y6: =R42 -> -1 | Z6: =I42 -> -1 | AA6: =SUMIF(U6:Z6, ">0") -> 1 | AB6: =W10 -> 4 | AC6: =AA6 -> 1 | AD6: =AB6-AC6+(0.01*AD16)+(0.001*AD26) -> 2.829 | AE6: =T6 -> Tjeard | AG6: -1.068 | AH6: Mittens | AI6: TBC
L7: Match 5 | M7: =C105 -> Berend | N7: =E105 -> Judith | O7: =if(AND(C121 = 0, F121 = 0), "Pending", "") | T7: =H11 -> Daniel | U7: =O62 -> 1 | V7: =I122 -> 1 | W7: =C82 -> -1 | Y7: =L62 -> 0 | Z7: =R102 -> 1 | AA7: =SUMIF(U7:Z7, ">0") -> 3 | AB7: =X10 -> 1 | AC7: =AA7 -> 3 | AD7: =AB7-AC7+(0.01*AD17)+(0.001*AD27) -> -2.123 | AE7: =T7 -> Daniel | AG7: -1.152 | AH7: Judith
H8: Berend | L8: Match 6 | M8: =I25 -> Mittens | N8: =K25 -> Tjeard | O8: =if(AND(I41 = 0, L41 = 0), "Pending", "") | T8: =H12 -> Frank | U8: =O122 -> 1 | V8: =C62 -> -1 | W8: =O42 -> 1 | X8: =I62 -> 0 | Z8: =C102 -> 1 | AA8: =SUMIF(U8:Z8, ">0") -> 3 | AB8: =Y10 -> 1 | AC8: =AA8 -> 3 | AD8: =AB8-AC8+(0.01*AD18)+(0.001*AD28) -> -2.12 | AE8: =T8 -> Frank | AG8: -2.12 | AH8: Frank
H9: Judith | L9: Match 7 | M9: =I45 -> Daniel | N9: =K45 -> Frank | O9: =if(AND(I61 = 0, L61 = 0), "Pending", "") | T9: =H13 -> Mittens | U9: =F42 -> 1 | V9: =I82 -> 1 | W9: =L42 -> 1 | X9: =O102 -> -1 | Y9: =F102 -> -1 | AA9: =SUMIF(U9:Z9, ">0") -> 3 | AB9: =Z10 -> 2 | AC9: =AA9 -> 3 | AD9: =AB9-AC9+(0.01*AD19)+(0.001*AD29) -> -1.068 | AE9: =T9 -> Mittens | AG9: -2.123 | AH9: Daniel
H10: Tjeard | L10: Match 8 | M10: =I65 -> Judith | N10: =K65 -> Mittens | O10: =if(AND(I81 = 0, L81 = 0), "Pending", "") | T10: Matches Won | U10: =SUMIF(U4:U9, ">0" ,U4:U9) -> 4 | V10: =SUMIF(V4:V9, ">0" ,V4:V9) -> 2 | W10: =SUMIF(W4:W9, ">0" ,W4:W9) -> 4 | X10: =SUMIF(X4:X9, ">0" ,X4:X9) -> 1 | Y10: =SUMIF(Y4:Y9, ">0" ,Y4:Y9) -> 1 | Z10: =SUMIF(Z4:Z9, ">0" ,Z4:Z9) -> 2
H11: Daniel | L11: Match 9 | M11: =I85 -> Berend | N11: =K85 -> Tjeard | O11: =if(AND(I101 = 0, L101 = 0), "Pending", "") | U11: =U3 -> Berend | V11: =V3 -> Judith | W11: =W3 -> Tjeard | X11: =X3 -> Daniel | Y11: =Y3 -> Frank | Z11: =Z3 -> Mittens
H12: Frank | L12: Match 10 | M12: =I105 -> Judith | N12: =K105 -> Daniel | O12: =if(AND(I121 = 0, L121 = 0), "Pending", "")
H13: Mittens | L13: Match 11 | M13: =O25 -> Tjeard | N13: =Q25 -> Frank | O13: =if(AND(O41 = 0, R41 = 0), "Pending", "") | T13: Doubles | U13: =T14 -> Berend | V13: =T15 -> Judith | W13: =T16 -> Tjeard | X13: =T17 -> Daniel | Y13: =T18 -> Frank | Z13: =T19 -> Mittens | AA13: Doubles | AD13: Total | AG13: ORDER | AI13: BY POINTS
L14: Match 12 | M14: =O45 -> Berend | N14: =Q45 -> Daniel | O14: =if(AND(O61 = 0, R61 = 0), "Pending", "") | T14: =H8 -> Berend | V14: =E121 -> 2 | W14: =K101 -> 7 | X14: =Q61 -> 2 | Y14: =Q121 -> 1 | Z14: =D41 -> 5 | AA14: =SUMIF(U14:Z14, ">0") -> 17 | AD14: =-AA14 -> -17 | AE14: =T14 -> Berend | AG14: {=SORT(AD14:AE19, 1, FALSE)} -> -9 | AH14: Frank | AI14: Classify
L15: Match 13 | M15: =O65 -> Judith | N15: =Q65 -> Tjeard | O15: =if(AND(O81 = 0, R81 = 0), "Pending", "") | T15: =H9 -> Judith | U15: =D121 -> 2 | W15: =Q81 -> 3 | X15: =K121 -> 5 | Y15: =E61 -> 4 | Z15: =K81 -> 0 | AA15: =SUMIF(U15:Z15, ">0") -> 14 | AD15: =-AA15 -> -14 | AE15: =T15 -> Judith | AG15: -9 | AH15: Mittens | AI15: Classify
L16: Match 14 | M16: =O85 -> Daniel | N16: =Q85 -> Mittens | O16: =if(AND(O101 = 0, R101 = 0), "Pending", "") | T16: =H10 -> Tjeard | U16: =J101 -> 7 | V16: =P81 -> 3 | X16: =E81 -> 3 | Y16: =Q41 -> 2 | Z16: =J41 -> 3 | AA16: =SUMIF(U16:Z16, ">0") -> 18 | AD16: =-AA16 -> -18 | AE16: =T16 -> Tjeard | AG16: -11 | AH16: Daniel | AI16: TBC
L17: Match 15 | M17: =O105 -> Berend | N17: =Q105 -> Frank | O17: =if(AND(O121 = 0, R121 = 0), "Pending", "") | T17: =H11 -> Daniel | U17: =P61 -> 2 | V17: =J121 -> 5 | W17: =D81 -> 3 | Y17: =K61 -> 1 | Z17: =Q101 -> 0 | AA17: =SUMIF(U17:Z17, ">0") -> 11 | AD17: =-AA17 -> -11 | AE17: =T17 -> Daniel | AG17: -14 | AH17: Judith
T18: =H12 -> Frank | U18: =P121 -> 1 | V18: =D61 -> 4 | W18: =P41 -> 2 | X18: =J61 -> 1 | Z18: =D101 -> 1 | AA18: =SUMIF(U18:Z18, ">0") -> 9 | AD18: =-AA18 -> -9 | AE18: =T18 -> Frank | AG18: -17 | AH18: Berend
T19: =H13 -> Mittens | U19: =E41 -> 5 | V19: =J81 -> 0 | W19: =K41 -> 3 | X19: =P101 -> 0 | Y19: =E101 -> 1 | AA19: =SUMIF(U19:Z19, ">0") -> 9 | AD19: =-AA19 -> -9 | AE19: =T19 -> Mittens | AG19: -18 | AH19: Tjeard
T20: Doubles | U20: =SUM(U14:U19) -> 17 | V20: =SUM(V14:V19) -> 14 | W20: =SUM(W14:W19) -> 18 | X20: =SUM(X14:X19) -> 11 | Y20: =SUM(Y14:Y19) -> 9 | Z20: =SUM(Z14:Z19) -> 9
U21: =U13 -> Berend | V21: =V13 -> Judith | W21: =W13 -> Tjeard | X21: =X13 -> Daniel | Y21: =Y13 -> Frank | Z21: =Z13 -> Mittens
AD22: 50
D23: INPUT | J23: INPUT | P23: INPUT | T23: POINTS | U23: =T24 -> Berend | V23: =T25 -> Judith | W23: =T26 -> Tjeard | X23: =T27 -> Daniel | Y23: =T28 -> Frank | Z23: =T29 -> Mittens | AA23: Points Lost | AB23: Won | AC23: Lost | AD23: Total | AG23: ORDER | AI23: BY POINTS
T24: =H8 -> Berend | V24: =F121 -> 8 | W24: =L101 -> 6 | X24: =R61 -> 7 | Y24: =R121 -> 7 | Z24: =C41 -> 5 | AA24: =SUMIF(U24:Z24, ">0") -> 33 | AB24: =U30 -> 57 | AC24: =AA24 -> 33 | AD24: =AB24-AC24 -> 24 | AE24: =T24 -> Berend | AG24: {=SORT(AD24:AE29, 1, FALSE)} -> 24 | AH24: Berend | AI24: Classify
B25: Match 1 | C25: =T19 -> Mittens | E25: =T14 -> Berend | H25: Match 6 | I25: =T19 -> Mittens | K25: =T16 -> Tjeard | N25: Match 11 | O25: =T16 -> Tjeard | Q25: =T18 -> Frank | T25: =H9 -> Judith | U25: =C121 -> 14 | W25: =R81 -> 11 | X25: =L121 -> 7 | Y25: =F61 -> 10 | Z25: =L81 -> 12 | AA25: =SUMIF(U25:Z25, ">0") -> 54 | AB25: =V30 -> 42 | AC25: =AA25 -> 54 | AD25: =AB25-AC25 -> -12 | AE25: =T25 -> Judith | AG25: 22 | AH25: Mittens | AI25: Classify
B26: Exchange 1 | C26: =IF(AND(D26>0,E26>0), 0, D26) | E26: 2 | F26: =IF(AND(D26>0,E26>0), 0, E26) -> 2 | H26: Exchange 1 | I26: =IF(AND(J26>0,K26>0), 0, J26) -> 0 | J26: 2 | K26: 3 | L26: =IF(AND(J26>0,K26>0), 0, K26) -> 0 | N26: Exchange 1 | O26: =IF(AND(P26>0,Q26>0), 0, P26) -> 1 | P26: 1 | R26: =IF(AND(P26>0,Q26>0), 0, Q26) | T26: =H10 -> Tjeard | U26: =I101 -> 5 | V26: =O81 -> 3 | X26: =F81 -> 15 | Y26: =R41 -> 7 | Z26: =I41 -> 10 | AA26: =SUMIF(U26:Z26, ">0") -> 40 | AB26: =W30 -> 49 | AC26: =AA26 -> 40 | AD26: =AB26-AC26 -> 9 | AE26: =T26 -> Tjeard | AG26: 9 | AH26: Tjeard | AI26: TBC
B27: Exchange 2 | C27: =IF(AND(D27>0,E27>0), 0, D27) -> 0 | D27: 3 | E27: 2 | F27: =IF(AND(D27>0,E27>0), 0, E27) -> 0 | H27: Exchange 2 | I27: =IF(AND(J27>0,K27>0), 0, J27) -> 0 | J27: 3 | K27: 2 | L27: =IF(AND(J27>0,K27>0), 0, K27) -> 0 | N27: Exchange 2 | O27: =IF(AND(P27>0,Q27>0), 0, P27) -> 0 | P27: 3 | Q27: 2 | R27: =IF(AND(P27>0,Q27>0), 0, Q27) -> 0 | T27: =H11 -> Daniel | U27: =O61 -> 13 | V27: =I121 -> 10 | W27: =C81 -> 7 | Y27: =L61 -> 9 | Z27: =R101 -> 16 | AA27: =SUMIF(U27:Z27, ">0") -> 55 | AB27: =X30 -> 42 | AC27: =AA27 -> 55 | AD27: =AB27-AC27 -> -13 | AE27: =T27 -> Daniel | AG27: -12 | AH27: Judith
B28: Exchange 3 | C28: =IF(AND(D28>0,E28>0), 0, D28) -> 0 | D28: 3 | E28: 2 | F28: =IF(AND(D28>0,E28>0), 0, E28) -> 0 | H28: Exchange 3 | I28: =IF(AND(J28>0,K28>0), 0, J28) | K28: 3 | L28: =IF(AND(J28>0,K28>0), 0, K28) -> 3 | N28: Exchange 3 | O28: =IF(AND(P28>0,Q28>0), 0, P28) | Q28: 3 | R28: =IF(AND(P28>0,Q28>0), 0, Q28) -> 3 | T28: =H12 -> Frank | U28: =O121 -> 16 | V28: =C61 -> 8 | W28: =O41 -> 14 | X28: =I61 -> 9 | Z28: =C101 -> 18 | AA28: =SUMIF(U28:Z28, ">0") -> 65 | AB28: =Y30 -> 35 | AC28: =AA28 -> 65 | AD28: =AB28-AC28 -> -30 | AE28: =T28 -> Frank | AG28: -13 | AH28: Daniel
B29: Exchange 4 | C29: =IF(AND(D29>0,E29>0), 0, D29) -> 2 | D29: 2 | F29: =IF(AND(D29>0,E29>0), 0, E29) | H29: Exchange 4 | I29: =IF(AND(J29>0,K29>0), 0, J29) | K29: 3 | L29: =IF(AND(J29>0,K29>0), 0, K29) -> 3 | N29: Exchange 4 | O29: =IF(AND(P29>0,Q29>0), 0, P29) | Q29: 2 | R29: =IF(AND(P29>0,Q29>0), 0, Q29) -> 2 | T29: =H13 -> Mittens | U29: =F41 -> 9 | V29: =I81 -> 13 | W29: =L41 -> 11 | X29: =O101 -> 4 | Y29: =F101 -> 2 | AA29: =SUMIF(U29:Z29, ">0") -> 39 | AB29: =Z30 -> 61 | AC29: =AA29 -> 39 | AD29: =AB29-AC29 -> 22 | AE29: =T29 -> Mittens | AG29: -30 | AH29: Frank
B30: Exchange 5 | C30: =IF(AND(D30>0,E30>0), 0, D30) -> 0 | D30: 2 | E30: 2 | F30: =IF(AND(D30>0,E30>0), 0, E30) -> 0 | H30: Exchange 5 | I30: =IF(AND(J30>0,K30>0), 0, J30) -> 2 | J30: 2 | L30: =IF(AND(J30>0,K30>0), 0, K30) | N30: Exchange 5 | O30: =IF(AND(P30>0,Q30>0), 0, P30) | Q30: 2 | R30: =IF(AND(P30>0,Q30>0), 0, Q30) -> 2 | T30: Points Won | U30: =SUM(U24:U29) -> 57 | V30: =SUM(V24:V29) -> 42 | W30: =SUM(W24:W29) -> 49 | X30: =SUM(X24:X29) -> 42 | Y30: =SUM(Y24:Y29) -> 35 | Z30: =SUM(Z24:Z29) -> 61
B31: Exchange 6 | C31: =IF(AND(D31>0,E31>0), 0, D31) | E31: 3 | F31: =IF(AND(D31>0,E31>0), 0, E31) -> 3 | H31: Exchange 6 | I31: =IF(AND(J31>0,K31>0), 0, J31) | K31: 3 | L31: =IF(AND(J31>0,K31>0), 0, K31) -> 3 | N31: Exchange 6 | O31: =IF(AND(P31>0,Q31>0), 0, P31) -> 0 | P31: 3 | Q31: 2 | R31: =IF(AND(P31>0,Q31>0), 0, Q31) -> 0 | U31: =U23 -> Berend | V31: =V23 -> Judith | W31: =W23 -> Tjeard | X31: =X23 -> Daniel | Y31: =Y23 -> Frank | Z31: =Z23 -> Mittens
B32: Exchange 7 | C32: =IF(AND(D32>0,E32>0), 0, D32) | E32: 2 | F32: =IF(AND(D32>0,E32>0), 0, E32) -> 2 | H32: Exchange 7 | I32: =IF(AND(J32>0,K32>0), 0, J32) -> 3 | J32: 3 | L32: =IF(AND(J32>0,K32>0), 0, K32) | N32: Exchange 7 | O32: =IF(AND(P32>0,Q32>0), 0, P32) -> 2 | P32: 2 | R32: =IF(AND(P32>0,Q32>0), 0, Q32)
B33: Exchange 8 | C33: =IF(AND(D33>0,E33>0), 0, D33) | E33: 2 | F33: =IF(AND(D33>0,E33>0), 0, E33) -> 2 | H33: Exchange 8 | I33: =IF(AND(J33>0,K33>0), 0, J33) -> 0 | J33: 3 | K33: 2 | L33: =IF(AND(J33>0,K33>0), 0, K33) -> 0 | N33: Exchange 8 | O33: =IF(AND(P33>0,Q33>0), 0, P33) -> 3 | P33: 3 | R33: =IF(AND(P33>0,Q33>0), 0, Q33)
B34: Exchange 9 | C34: =IF(AND(D34>0,E34>0), 0, D34) -> 3 | D34: 3 | F34: =IF(AND(D34>0,E34>0), 0, E34) | H34: Exchange 9 | I34: =IF(AND(J34>0,K34>0), 0, J34) -> 3 | J34: 3 | L34: =IF(AND(J34>0,K34>0), 0, K34) | N34: Exchange 9 | O34: =IF(AND(P34>0,Q34>0), 0, P34) -> 3 | P34: 3 | R34: =IF(AND(P34>0,Q34>0), 0, Q34)
B35: Exchange 10 | C35: =IF(AND(D35>0,E35>0), 0, D35) -> 0 | D35: 2 | E35: 3 | F35: =IF(AND(D35>0,E35>0), 0, E35) -> 0 | H35: Exchange 10 | I35: =IF(AND(J35>0,K35>0), 0, J35) | K35: 2 | L35: =IF(AND(J35>0,K35>0), 0, K35) -> 2 | N35: Exchange 10 | O35: =IF(AND(P35>0,Q35>0), 0, P35) -> 2 | P35: 2 | R35: =IF(AND(P35>0,Q35>0), 0, Q35)
B36: Exchange 11 | C36: =IF(AND(D36>0,E36>0), 0, D36) -> 0 | D36: 2 | E36: 2 | F36: =IF(AND(D36>0,E36>0), 0, E36) -> 0 | H36: Exchange 11 | I36: =IF(AND(J36>0,K36>0), 0, J36) -> 2 | J36: 2 | L36: =IF(AND(J36>0,K36>0), 0, K36) | N36: Exchange 11 | O36: =IF(AND(P36>0,Q36>0), 0, P36) -> 3 | P36: 3 | R36: =IF(AND(P36>0,Q36>0), 0, Q36)
B37: Exchange 12 | C37: =IF(AND(D37>0,E37>0), 0, D37) | F37: =IF(AND(D37>0,E37>0), 0, E37) | H37: Exchange 12 | I37: =IF(AND(J37>0,K37>0), 0, J37) | L37: =IF(AND(J37>0,K37>0), 0, K37) | N37: Exchange 12 | O37: =IF(AND(P37>0,Q37>0), 0, P37) | R37: =IF(AND(P37>0,Q37>0), 0, Q37)
B38: Exchange 13 | C38: =IF(AND(D38>0,E38>0), 0, D38) | F38: =IF(AND(D38>0,E38>0), 0, E38) | H38: Exchange 13 | I38: =IF(AND(J38>0,K38>0), 0, J38) | L38: =IF(AND(J38>0,K38>0), 0, K38) | N38: Exchange 13 | O38: =IF(AND(P38>0,Q38>0), 0, P38) | R38: =IF(AND(P38>0,Q38>0), 0, Q38)
B39: Exchange 14 | C39: =IF(AND(D39>0,E39>0), 0, D39) | F39: =IF(AND(D39>0,E39>0), 0, E39) | H39: Exchange 14 | I39: =IF(AND(J39>0,K39>0), 0, J39) | L39: =IF(AND(J39>0,K39>0), 0, K39) | N39: Exchange 14 | O39: =IF(AND(P39>0,Q39>0), 0, P39) | R39: =IF(AND(P39>0,Q39>0), 0, Q39)
B40: Exchange 15 | C40: =IF(AND(D40>0,E40>0), 0, D40) | F40: =IF(AND(D40>0,E40>0), 0, E40) | H40: Exchange 15 | I40: =IF(AND(J40>0,K40>0), 0, J40) | L40: =IF(AND(J40>0,K40>0), 0, K40) | N40: Exchange 15 | O40: =IF(AND(P40>0,Q40>0), 0, P40) | R40: =IF(AND(P40>0,Q40>0), 0, Q40)
B41: Won Points | C41: =SUM(C26:C40) -> 5 | D41: =COUNTIFS(D26:D40, "<>0", D26:D40, "<>", E26:E40, "<>0", E26:E40, "<>") -> 5 | E41: =COUNTIFS(D26:D40, "<>0", D26:D40, "<>", E26:E40, "<>0", E26:E40, "<>") -> 5 | F41: =SUM(F26:F40) -> 9 | H41: Won Points | I41: =SUM(I26:I40) -> 10 | J41: =COUNTIFS(J26:J40, "<>0", J26:J40, "<>", K26:K40, "<>0", K26:K40, "<>") -> 3 | K41: =COUNTIFS(J26:J40, "<>0", J26:J40, "<>", K26:K40, "<>0", K26:K40, "<>") -> 3 | L41: =SUM(L26:L40) -> 11 | N41: Won Points | O41: =SUM(O26:O40) -> 14 | P41: =COUNTIFS(P26:P40, "<>0", P26:P40, "<>", Q26:Q40, "<>0", Q26:Q40, "<>") -> 2 | Q41: =COUNTIFS(P26:P40, "<>0", P26:P40, "<>", Q26:Q40, "<>0", Q26:Q40, "<>") -> 2 | R41: =SUM(R26:R40) -> 7
B42: Won Match | C42: =D42 -> -1 | D42: =IF(C41>F41, 1, (IF(C41=F41, 0, -1))) -> -1 | E42: =IF(F41>C41, 1, (IF(F41=C41, 0, -1))) -> 1 | F42: =E42 -> 1 | H42: Won Match | I42: =J42 -> -1 | J42: =IF(I41>L41, 1, (IF(I41=L41, 0, -1))) -> -1 | K42: =IF(L41>I41, 1, (IF(L41=I41, 0, -1))) -> 1 | L42: =K42 -> 1 | N42: Won Match | O42: =P42 -> 1 | P42: =IF(O41>R41, 1, (IF(O41=R41, 0, -1))) -> 1 | Q42: =IF(R41>O41, 1, (IF(R41=O41, 0, -1))) -> -1 | R42: =Q42 -> -1
...

Sheet Eliminations
B2: Pool 1 | C2: Pool 2 | D2: Pool 3 | K2: Bronze Scores | N2: Bronze Sorted
A3: 1 | B3: =Pool_1!AH4 -> Tim the Burgundy Enchanter | C3: =Pool_2!AH4 -> Jesse | D3: =Pool_3!AH4 -> Berend | K3: =Pool_1!AH6 -> Teun | L3: =Pool_1!AG6 -> 0.942 | N3: {=SORT(K3:L5, 2, false)} -> Teun | O3: 0.942 | AL3: =O79 | AM3: =Q79 | AN3: =O105 | AQ3: =Q105
A4: 2 | B4: =Pool_1!AH5 -> Eminence Bruin | C4: =Pool_2!AH5 -> Rory | D4: =Pool_3!AH5 -> Tjeard | F4: Best Bronze 1 | G4: Best Bronze 2 | K4: =Pool_2!AH6 -> Arjan | L4: =Pool_2!AG6 -> 0.868 | N4: Arjan | O4: 0.868 | T4: MATCHES | U4: =C27 -> Jesse | V4: =E27 -> Arjan | W4: =C53 -> Tjeard | X4: =E53 -> Rory | Y4: =C79 -> Tim the Burgundy Enchanter | Z4: =E79 -> Eminence Bruin | AA4: =C105 -> Teun | AB4: =E105 -> Berend | AC4: Lost | AD4: Won | AE4: Total | AI4: =I27 -> Jesse | AJ4: =K27 -> Tjeard | AK4: =I53 -> Eminence Bruin | AL4: =K53 -> Berend | AM4: Lost | AN4: Won | AO4: Total | AS4: =O27 -> Jesse | AT4: =Q27 -> Berend | AU4: =O53 -> Tjeard | AV4: =Q53 -> Eminence Bruin | AW4: Lost | AX4: Won | AY4: Total
A5: 3 | B5: =Pool_1!AH6 -> Teun | C5: =Pool_2!AH6 -> Arjan | D5: =Pool_3!AH6 -> Mittens | F5: =N3 -> Teun | G5: =N4 -> Arjan | K5: =Pool_3!AH6 -> Mittens | L5: =Pool_3!AG6 -> -1.068 | N5: Mittens | O5: -1.068 | T5: =C27 -> Jesse | V5: =F49 -> -1 | AC5: =sumif(U5:AB5, ">0") -> 0 | AD5: =U13 -> 1 | AE5: =AD5+(0.001*(AE17/AE$25)) -> 1.0002381 | AF5: =T5 -> Jesse | AH5: =I27 -> Jesse | AJ5: =L49 -> -1 | AM5: =sumif(AH5:AL5, ">0") -> 0 | AN5: =AI9 -> 1 | AO5: =AN5-AM5+(0.01*(AO17/AO$21)) -> 1.0046154 | AP5: =AH5 -> Jesse | AR5: =O27 -> Jesse | AT5: =R49 -> 1 | AW5: =sumif(AS5:AV5, ">0") -> 1 | AX5: =AS9 -> 0 | AY5: =AX5+(0.1*(AY17/AY$21)) -> -0.025 | AZ5: =AR5 -> Jesse | BC5: =AF5 -> Jesse | BD5: =AE5 -> 1.0002381 | BE5: =AP5 -> Jesse | BF5: =AO5 -> 1.0046154 | BG5: =AZ5 -> Jesse | BH5: =AY5 -> -0.025 | BJ5: =sumif(BC$5:BG$12,BC$5:BC$12,BD$5:BH$12) -> 1.9798535 | BK5: =BC5:BC12 -> Jesse | BM5: {=sort(BJ5:BK12,1,FALSE)} -> 3.0299487 | BN5: Berend
T6: =E27 -> Arjan | U6: =C49 -> 1 | AC6: =sumif(U6:AB6, ">0") -> 1 | AD6: =V13 -> 0 | AE6: =AD6+(0.001*(AE18/AE$25)) -> -0.00023809524 | AF6: =T6 -> Arjan | AH6: =K27 -> Tjeard | AI6: =I49 -> 1 | AM6: =sumif(AH6:AL6, ">0") -> 1 | AN6: =AJ9 -> 0 | AO6: =AN6+(0.01*(AO18/AO$21)) -> -0.0046153846 | AP6: =AH6 -> Tjeard | AR6: =Q27 -> Berend | AS6: =O49 -> -1 | AW6: =sumif(AS6:AV6, ">0") -> 0 | AX6: =AT9 -> 1 | AY6: =AX6+(0.1*(AY18/AY$21)) -> 1.025 | AZ6: =AR6 -> Berend | BC6: =AF6 -> Arjan | BD6: =AE6 -> -0.00023809524 | BE6: =AP6 -> Tjeard | BF6: =AO6 -> -0.0046153846 | BG6: =AZ6 -> Berend | BH6: =AY6 -> 1.025 | BJ6: =sumif(BC$5:BG$12,BC$5:BC$12,BD$5:BH$12) -> -0.00023809524 | BK6: =BC6:BC13 -> Arjan | BM6: 1.9798535 | BN6: Jesse
T7: =C53 -> Tjeard | X7: =F75 -> -1 | AC7: =sumif(U7:AB7, ">0") -> 0 | AD7: =W13 -> 1 | AE7: =AD7+(0.001*(AE19/AE$25)) -> 1.0000952 | AF7: =T7 -> Tjeard | AH7: =I53 -> Eminence Bruin | AL7: =L75 -> 1 | AM7: =sumif(AH7:AL7, ">0") -> 1 | AN7: =AK9 -> 0 | AO7: =AN7+(0.01*(AO19/AO$21)) -> -0.0046153846 | AP7: =AH7 -> Eminence Bruin | AR7: =O53 -> Tjeard | AV7: =R75*0.5 -> -0.5 | AW7: =sumif(AS7:AV7, ">0") -> 0 | AX7: =AU9 -> 0.5 | AY7: =AX7+(0.1*(AY19/AY$21)) -> 0.55 | AZ7: =AR7 -> Tjeard | BC7: =AF7 -> Tjeard | BD7: =AE7 -> 1.0000952 | BE7: =AP7 -> Eminence Bruin | BF7: =AO7 -> -0.0046153846 | BG7: =AZ7 -> Tjeard | BH7: =AY7 -> 0.55 | BJ7: =sumif(BC$5:BG$12,BC$5:BC$12,BD$5:BH$12) -> 1.5454799 | BK7: =BC7:BC14 -> Tjeard | BM7: 1.5454799 | BN7: Tjeard
K8: Silver Scores | N8: Silver Sorted | T8: =E53 -> Rory | W8: =C75 -> 1 | AC8: =sumif(U8:AB8, ">0") -> 1 | AD8: =X13 -> 0 | AE8: =AD8+(0.001*(AE20/AE$25)) -> -9.5238095e-05 | AF8: =T8 -> Rory | AH8: =K53 -> Berend | AK8: =I75 -> -1 | AM8: =sumif(AH8:AL8, ">0") -> 0 | AN8: =AL9 -> 1 | AO8: =AN8+(0.01*(AO20/AO$21)) -> 1.0046154 | AP8: =AH8 -> Berend | AR8: =Q53 -> Eminence Bruin | AU8: =O75*0.5 -> 0.5 | AW8: =sumif(AS8:AV8, ">0") -> 0.5 | AX8: =AV9 -> 0 | AY8: =AX8+(0.1*(AY20/AY$21)) -> -0.05 | AZ8: =AR8 -> Eminence Bruin | BC8: =AF8 -> Rory | BD8: =AE8 -> -9.5238095e-05 | BE8: =AP8 -> Berend | BF8: =AO8 -> 1.0046154 | BG8: =AZ8 -> Eminence Bruin | BH8: =AY8 -> -0.05 | BJ8: =sumif(BC$5:BG$12,BC$5:BC$12,BD$5:BH$12) -> -9.5238095e-05 | BK8: =BC8:BC15 -> Rory | BM8: 0.94567033 | BN8: Eminence Bruin
K9: =Pool_1!AH5 -> Eminence Bruin | L9: =Pool_1!AG5 -> 1.887 | N9: {=SORT(K9:L11, 2, false)} -> Tjeard | O9: 2.829 | T9: =C79 -> Tim the Burgundy Enchanter | Z9: =F101 -> 1 | AC9: =sumif(U9:AB9, ">0") -> 1 | AD9: =Y13 -> 0 | AE9: =AD9+(0.001*(AE21/AE$25)) -> -0.00028571429 | AF9: =T9 -> Tim the Burgundy Enchanter | AG9: =Q79 | AH9: Won | AI9: =SUMIF(AI5:AI8, ">0", AI5:AI8) -> 1 | AJ9: =SUMIF(AJ5:AJ8, ">0", AJ5:AJ8) -> 0 | AK9: =SUMIF(AK5:AK8, ">0", AK5:AK8) -> 0 | AL9: =SUMIF(AL5:AL8, ">0", AL5:AL8) -> 1 | AN9: =AI13 | AR9: Won | AS9: =SUMIF(AS5:AS8, ">0", AS5:AS8) -> 0 | AT9: =SUMIF(AT5:AT8, ">0", AT5:AT8) -> 1 | AU9: =SUMIF(AU5:AU8, ">0", AU5:AU8) -> 0.5 | AV9: =SUMIF(AV5:AV8, ">0", AV5:AV8) -> 0 | AX9: =AS13 | BC9: =AF9 -> Tim the Burgundy Enchanter | BD9: =AE9 -> -0.00028571429 | BE9: =AP9 | BF9: =AO9 | BJ9: =sumif(BC$5:BG$12,BC$5:BC$12,BD$5:BH$12) -> -0.00028571429 | BK9: =BC9:BC16 -> Tim the Burgundy Enchanter | BM9: -9.5238095e-05 | BN9: Rory
A10: Quarter Final 1 | B10: =N15 -> Jesse | K10: =Pool_2!AH5 -> Rory | L10: =Pool_2!AG5 -> 1.893 | N10: Rory | O10: 1.893 | T10: =E79 -> Eminence Bruin | Y10: =C101 -> -1 | AC10: =sumif(U10:AB10, ">0") -> 0 | AD10: =Z13 -> 1 | AE10: =AD10+(0.001*(AE22/AE$25)) -> 1.0002857 | AF10: =T10 -> Eminence Bruin | AG10: =O105 | AN10: =AJ13 | BC10: =AF10 -> Eminence Bruin | BD10: =AE10 -> 1.0002857 | BE10: =AP10 | BF10: =AO10 | BJ10: =sumif(BC$5:BG$12,BC$5:BC$12,BD$5:BH$12) -> 0.94567033 | BK10: =BC10:BC17 -> Eminence Bruin | BM10: -0.00023809524 | BN10: Arjan
B11: =G5 -> Arjan | K11: =Pool_3!AH5 -> Tjeard | L11: =Pool_3!AG5 -> 2.829 | N11: Eminence Bruin | O11: 1.887 | T11: =C105 -> Teun | AB11: =F127 -> 1 | AC11: =sumif(U11:AB11, ">0") -> 1 | AD11: =AA13 -> 0 | AE11: =AD11+(0.001*(AE23/AE$25)) -> -0.00033333333 | AF11: =T11 -> Teun | AG11: =Q105 | AN11: =AK13 | BC11: =AF11 -> Teun | BD11: =AE11 -> -0.00033333333 | BE11: =AP11 | BF11: =AO11 | BJ11: =sumif(BC$5:BG$12,BC$5:BC$12,BD$5:BH$12) -> -0.00033333333 | BK11: =BC11:BC18 -> Teun | BM11: -0.00028571429 | BN11: Tim the Burgundy Enchanter
C12: Semifinal 1 | D12: =E50 -> Jesse | T12: =E105 -> Berend | AA12: =C127 -> -1 | AC12: =sumif(U12:AB12, ">0") -> 0 | AD12: =AB13 -> 1 | AE12: =AD12+(0.001*(AE24/AE$25)) -> 1.0003333 | AF12: =T12 -> Berend | AN12: =AL13 | BC12: =AF12 -> Berend | BD12: =AE12 -> 1.0003333 | BE12: =AP12 | BF12: =AO12 | BJ12: =sumif(BC$5:BG$12,BC$5:BC$12,BD$5:BH$12) -> 3.0299487 | BK12: =BC12:BC19 -> Berend | BM12: -0.00033333333 | BN12: Teun
A13: Quarter Final 2 | B13: =N9 -> Tjeard | D13: =E76 -> Tjeard | T13: Won | U13: =SUMIF(U5:U12, ">0", U5:U12) -> 1 | V13: =SUMIF(V5:V12, ">0", V5:V12) -> 0 | W13: =SUMIF(W5:W12, ">0", W5:W12) -> 1 | X13: =SUMIF(X5:X12, ">0", X5:X12) -> 0 | Y13: =SUMIF(Y5:Y12, ">0", Y5:Y12) -> 0 | Z13: =SUMIF(Z5:Z12, ">0", Z5:Z12) -> 1 | AA13: =SUMIF(AA5:AA12, ">0", AA5:AA12) -> 0 | AB13: =SUMIF(AB5:AB12, ">0", AB5:AB12) -> 1
B14: =N10 -> Rory | E14: Final | F14: =K50 -> Jesse | K14: Gold Scores | N14: Gold Sorted
F15: =K76 -> Berend | K15: =Pool_1!AH4 -> Tim the Burgundy Enchanter | L15: =Pool_1!AG4 -> 1.953 | N15: {=SORT(K15:L17, 2, false)} -> Jesse | O15: 4.927
A16: Quarter Final 3 | B16: =N17 -> Tim the Burgundy Enchanter | K16: =Pool_2!AH4 -> Jesse | L16: =Pool_2!AG4 -> 4.927 | N16: Berend | O16: 2.854 | T16: POINTS | U16: =C27 -> Jesse | V16: =E27 -> Arjan | W16: =C53 -> Tjeard | X16: =E53 -> Rory | Y16: =C79 -> Tim the Burgundy Enchanter | Z16: =E79 -> Eminence Bruin | AA16: =C105 -> Teun | AB16: =E105 -> Berend | AC16: Lost | AD16: Won | AE16: Total | AI16: =I27 -> Jesse | AJ16: =K27 -> Tjeard | AK16: =I53 -> Eminence Bruin | AL16: =K53 -> Berend | AM16: Lost | AN16: Won | AO16: Total | AS16: =O27 -> Jesse | AT16: =Q27 -> Berend | AU16: =O53 -> Tjeard | AV16: =Q53 -> Eminence Bruin | AW16: Lost | AX16: Won | AY16: Total
B17: =N11 -> Eminence Bruin | D17: =E102 -> Eminence Bruin | K17: =Pool_3!AH4 -> Berend | L17: =Pool_3!AG4 -> 2.854 | N17: Tim the Burgundy Enchanter | O17: 1.953 | T17: =C27 -> Jesse | V17: =F48 -> 5 | AC17: =sumif(U17:AB17, ">0") -> 5 | AD17: =U25 -> 10 | AE17: =AD17-AC17 -> 5 | AF17: =T17 -> Jesse | AH17: =I27 -> Jesse | AJ17: =L48 -> 9 | AM17: =sumif(AH17:AL17, ">0") -> 9 | AN17: =AI21 -> 15 | AO17: =AN17-AM17 -> 6 | AP17: =AH17 -> Jesse | AR17: =O27 -> Jesse | AT17: =R48 -> 9 | AW17: =sumif(AS17:AV17, ">0") -> 9 | AX17: =AS21 -> 8 | AY17: =AX17-AW17 -> -1 | AZ17: =AR17 -> Jesse | BC17: =AF17 -> Jesse | BD17: =AE17 -> 5 | BE17: =AP17 -> Jesse | BF17: =AO17 -> 6 | BG17: =AZ17 -> Jesse | BH17: =AY17 -> -1 | BJ17: =sumif(BC$17:BG$24,BC$17:BC$24,BD$17:BH$24) -> 10 | BK17: =BC17:BC24 -> Jesse
C18: Semifinal 2 | D18: =E128 -> Berend | T18: =E27 -> Arjan | U18: =C48 -> 10 | AC18: =sumif(U18:AB18, ">0") -> 10 | AD18: =V25 -> 5 | AE18: =AD18-AC18 -> -5 | AF18: =T18 -> Arjan | AH18: =K27 -> Tjeard | AI18: =I48 -> 15 | AM18: =sumif(AH18:AL18, ">0") -> 15 | AN18: =AJ21 -> 9 | AO18: =AN18-AM18 -> -6 | AP18: =AH18 -> Tjeard | AR18: =Q27 -> Berend | AS18: =O48 -> 8 | AW18: =sumif(AS18:AV18, ">0") -> 8 | AX18: =AT21 -> 9 | AY18: =AX18-AW18 -> 1 | AZ18: =AR18 -> Berend | BC18: =AF18 -> Arjan | BD18: =AE18 -> -5 | BE18: =AP18 -> Tjeard | BF18: =AO18 -> -6 | BG18: =AZ18 -> Berend | BH18: =AY18 -> 1 | BJ18: =sumif(BC$17:BG$24,BC$17:BC$24,BD$17:BH$24) -> -5 | BK18: =BC18:BC25 -> Arjan
A19: Quarter Final 4 | B19: =F5 -> Teun | T19: =C53 -> Tjeard | X19: =F74 -> 8 | AC19: =sumif(U19:AB19, ">0") -> 8 | AD19: =W25 -> 10 | AE19: =AD19-AC19 -> 2 | AF19: =T19 -> Tjeard | AH19: =I53 -> Eminence Bruin | AL19: =L74 -> 11 | AM19: =sumif(AH19:AL19, ">0") -> 11 | AN19: =AK21 -> 5 | AO19: =AN19-AM19 -> -6 | AP19: =AH19 -> Eminence Bruin | AR19: =O53 -> Tjeard | AV19: =R74 -> 8 | AW19: =sumif(AS19:AV19, ">0") -> 8 | AX19: =AU21 -> 10 | AY19: =AX19-AW19 -> 2 | AZ19: =AR19 -> Tjeard | BC19: =AF19 -> Tjeard | BD19: =AE19 -> 2 | BE19: =AP19 -> Eminence Bruin | BF19: =AO19 -> -6 | BG19: =AZ19 -> Tjeard | BH19: =AY19 -> 2 | BJ19: =sumif(BC$17:BG$24,BC$17:BC$24,BD$17:BH$24) -> -2 | BK19: =BC19:BC26 -> Tjeard
B20: =N16 -> Berend | T20: =E53 -> Rory | W20: =C74 -> 10 | AC20: =sumif(U20:AB20, ">0") -> 10 | AD20: =X25 -> 8 | AE20: =AD20-AC20 -> -2 | AF20: =T20 -> Rory | AH20: =K53 -> Berend | AK20: =I74 -> 5 | AM20: =sumif(AH20:AL20, ">0") -> 5 | AN20: =AL21 -> 11 | AO20: =AN20-AM20 -> 6 | AP20: =AH20 -> Berend | AR20: =Q53 -> Eminence Bruin | AU20: =O74 -> 10 | AW20: =sumif(AS20:AV20, ">0") -> 10 | AX20: =AV21 -> 8 | AY20: =AX20-AW20 -> -2 | AZ20: =AR20 -> Eminence Bruin | BC20: =AF20 -> Rory | BD20: =AE20 -> -2 | BE20: =AP20 -> Berend | BF20: =AO20 -> 6 | BG20: =AZ20 -> Eminence Bruin | BH20: =AY20 -> -2 | BJ20: =sumif(BC$17:BG$24,BC$17:BC$24,BD$17:BH$24) -> -2 | BK20: =BC20:BC27 -> Rory
E21: Bronze | F21: =K51 -> Tjeard | T21: =C79 -> Tim the Burgundy Enchanter | Z21: =F100 -> 13 | AC21: =sumif(U21:AB21, ">0") -> 13 | AD21: =Y25 -> 7 | AE21: =AD21-AC21 -> -6 | AF21: =T21 -> Tim the Burgundy Enchanter | AH21: Won | AI21: =SUMIF(AI17:AI20, ">0", AI17:AI20) -> 15 | AJ21: =SUMIF(AJ17:AJ20, ">0", AJ17:AJ20) -> 9 | AK21: =SUMIF(AK17:AK20, ">0", AK17:AK20) -> 5 | AL21: =SUMIF(AL17:AL20, ">0", AL17:AL20) -> 11 | AN21: =AI25 | AO21: =SUMIF(AO17:AO20,">0",AO17:AO20)+1 -> 13 | AR21: Won | AS21: =SUMIF(AS17:AS20, ">0", AS17:AS20) -> 8 | AT21: =SUMIF(AT17:AT20, ">0", AT17:AT20) -> 9 | AU21: =SUMIF(AU17:AU20, ">0", AU17:AU20) -> 10 | AV21: =SUMIF(AV17:AV20, ">0", AV17:AV20) -> 8 | AX21: =AS25 | AY21: =SUMIF(AY17:AY20,">0",AY17:AY20)+1 -> 4 | BC21: =AF21 -> Tim the Burgundy Enchanter | BD21: =AE21 -> -6 | BE21: =AP21 | BF21: =AO21 -> 13 | BJ21: =sumif(BC$17:BG$24,BC$17:BC$24,BD$17:BH$24) -> -6 | BK21: =BC21:BC28 -> Tim the Burgundy Enchanter
F22: =K77 -> Eminence Bruin | T22: =E79 -> Eminence Bruin | Y22: =C100 -> 7 | AC22: =sumif(U22:AB22, ">0") -> 7 | AD22: =Z25 -> 13 | AE22: =AD22-AC22 -> 6 | AF22: =T22 -> Eminence Bruin | AN22: =AJ25 | BC22: =AF22 -> Eminence Bruin | BD22: =AE22 -> 6 | BE22: =AP22 | BF22: =AO22 | BJ22: =sumif(BC$17:BG$24,BC$17:BC$24,BD$17:BH$24) -> -2 | BK22: =BC22:BC29 -> Eminence Bruin
T23: =C105 -> Teun | AB23: =F126 -> 16 | AC23: =sumif(U23:AB23, ">0") -> 16 | AD23: =AA25 -> 9 | AE23: =AD23-AC23 -> -7 | AF23: =T23 -> Teun | AN23: =AK25 | BC23: =AF23 -> Teun | BD23: =AE23 -> -7 | BE23: =AP23 | BF23: =AO23 | BJ23: =sumif(BC$17:BG$24,BC$17:BC$24,BD$17:BH$24) -> -7 | BK23: =BC23:BC30 -> Teun
T24: =E105 -> Berend | AA24: =C126 -> 9 | AC24: =sumif(U24:AB24, ">0") -> 9 | AD24: =AB25 -> 16 | AE24: =AD24-AC24 -> 7 | AF24: =T24 -> Berend | AN24: =AL25 | BC24: =AF24 -> Berend | BD24: =AE24 -> 7 | BE24: =AP24 | BF24: =AO24 | BJ24: =sumif(BC$17:BG$24,BC$17:BC$24,BD$17:BH$24) -> 14 | BK24: =BC24:BC31 -> Berend
T25: Won | U25: =SUMIF(U17:U24, ">0", U17:U24) -> 10 | V25: =SUMIF(V17:V24, ">0", V17:V24) -> 5 | W25: =SUMIF(W17:W24, ">0", W17:W24) -> 10 | X25: =SUMIF(X17:X24, ">0", X17:X24) -> 8 | Y25: =SUMIF(Y17:Y24, ">0", Y17:Y24) -> 7 | Z25: =SUMIF(Z17:Z24, ">0", Z17:Z24) -> 13 | AA25: =SUMIF(AA17:AA24, ">0", AA17:AA24) -> 9 | AB25: =SUMIF(AB17:AB24, ">0", AB17:AB24) -> 16 | AE25: =SUMIF(AE17:AE24,">0",AE17:AE24)+1 -> 21
B27: =A10 -> Quarter Final 1 | C27: =B10 -> Jesse | E27: =B11 -> Arjan | H27: =C12 -> Semifinal 1 | I27: =D12 -> Jesse | K27: =D13 -> Tjeard | N27: =E14 -> Final | O27: =F14 -> Jesse | Q27: =F15 -> Berend
B28: Exchange 1 | C28: =IF(AND(D28>0,E28>0), 0, D28) -> 2 | D28: 2 | F28: =IF(AND(D28>0,E28>0), 0, E28) | H28: Exchange 1 | I28: =IF(AND(J28>0,K28>0), 0, J28) -> 2 | J28: 2 | L28: =IF(AND(J28>0,K28>0), 0, K28) | N28: Exchange 1 | O28: =IF(AND(P28>0,Q28>0), 0, P28) -> 2 | P28: 2 | R28: =IF(AND(P28>0,Q28>0), 0, Q28)
B29: Exchange 2 | C29: =IF(AND(D29>0,E29>0), 0, D29) -> 0 | D29: 2 | E29: 2 | F29: =IF(AND(D29>0,E29>0), 0, E29) -> 0 | H29: Exchange 2 | I29: =IF(AND(J29>0,K29>0), 0, J29) -> 3 | J29: 3 | L29: =IF(AND(J29>0,K29>0), 0, K29) | N29: Exchange 2 | O29: =IF(AND(P29>0,Q29>0), 0, P29) | Q29: 2 | R29: =IF(AND(P29>0,Q29>0), 0, Q29) -> 2
B30: Exchange 3 | C30: =IF(AND(D30>0,E30>0), 0, D30) -> 2 | D30: 2 | F30: =IF(AND(D30>0,E30>0), 0, E30) | H30: Exchange 3 | I30: =IF(AND(J30>0,K30>0), 0, J30) -> 2 | J30: 2 | L30: =IF(AND(J30>0,K30>0), 0, K30) | N30: Exchange 3 | O30: =IF(AND(P30>0,Q30>0), 0, P30) | R30: =IF(AND(P30>0,Q30>0), 0, Q30)
B31: Exchange 4 | C31: =IF(AND(D31>0,E31>0), 0, D31) | E31: 2 | F31: =IF(AND(D31>0,E31>0), 0, E31) -> 2 | H31: Exchange 4 | I31: =IF(AND(J31>0,K31>0), 0, J31) -> 0 | J31: 2 | K31: 2 | L31: =IF(AND(J31>0,K31>0), 0, K31) -> 0 | N31: Exchange 4 | O31: =IF(AND(P31>0,Q31>0), 0, P31) -> 2 | P31: 2 | R31: =IF(AND(P31>0,Q31>0), 0, Q31)
B32: Exchange 5 | C32: =IF(AND(D32>0,E32>0), 0, D32) -> 0 | D32: 3 | E32: 2 | F32: =IF(AND(D32>0,E32>0), 0, E32) -> 0 | H32: Exchange 5 | I32: =IF(AND(J32>0,K32>0), 0, J32) -> 2 | J32: 2 | L32: =IF(AND(J32>0,K32>0), 0, K32) | N32: Exchange 5 | O32: =IF(AND(P32>0,Q32>0), 0, P32) -> 2 | P32: 2 | R32: =IF(AND(P32>0,Q32>0), 0, Q32)
B33: Exchange 6 | C33: =IF(AND(D33>0,E33>0), 0, D33) -> 0 | D33: 2 | E33: 3 | F33: =IF(AND(D33>0,E33>0), 0, E33) -> 0 | H33: Exchange 6 | I33: =IF(AND(J33>0,K33>0), 0, J33) | K33: 3 | L33: =IF(AND(J33>0,K33>0), 0, K33) -> 3 | N33: Exchange 6 | O33: =IF(AND(P33>0,Q33>0), 0, P33) | Q33: 3 | R33: =IF(AND(P33>0,Q33>0), 0, Q33) -> 3
B34: Exchange 7 | C34: =IF(AND(D34>0,E34>0), 0, D34) -> 2 | D34: 2 | F34: =IF(AND(D34>0,E34>0), 0, E34) | H34: Exchange 7 | I34: =IF(AND(J34>0,K34>0), 0, J34) | K34: 3 | L34: =IF(AND(J34>0,K34>0), 0, K34) -> 3 | N34: Exchange 7 | O34: =IF(AND(P34>0,Q34>0), 0, P34) -> 0 | P34: 2 | Q34: 3 | R34: =IF(AND(P34>0,Q34>0), 0, Q34) -> 0
B35: Exchange 8 | C35: =IF(AND(D35>0,E35>0), 0, D35) -> 2 | D35: 2 | F35: =IF(AND(D35>0,E35>0), 0, E35) | H35: Exchange 8 | I35: =IF(AND(J35>0,K35>0), 0, J35) -> 2 | J35: 2 | L35: =IF(AND(J35>0,K35>0), 0, K35) | N35: Exchange 8 | O35: =IF(AND(P35>0,Q35>0), 0, P35) -> 0 | P35: 2 | Q35: 2 | R35: =IF(AND(P35>0,Q35>0), 0, Q35) -> 0
B36: Exchange 9 | C36: =IF(AND(D36>0,E36>0), 0, D36) -> 2 | D36: 2 | F36: =IF(AND(D36>0,E36>0), 0, E36) | H36: Exchange 9 | I36: =IF(AND(J36>0,K36>0), 0, J36) | K36: 2 | L36: =IF(AND(J36>0,K36>0), 0, K36) -> 2 | N36: Exchange 9 | O36: =IF(AND(P36>0,Q36>0), 0, P36) -> 2 | P36: 2 | R36: =IF(AND(P36>0,Q36>0), 0, Q36)
B37: Exchange 10 | C37: =IF(AND(D37>0,E37>0), 0, D37) | E37: 3 | F37: =IF(AND(D37>0,E37>0), 0, E37) -> 3 | H37: Exchange 10 | I37: =IF(AND(J37>0,K37>0), 0, J37) -> 2 | J37: 2 | L37: =IF(AND(J37>0,K37>0), 0, K37) | N37: Exchange 10 | O37: =IF(AND(P37>0,Q37>0), 0, P37) -> 0 | P37: 2 | Q37: 2 | R37: =IF(AND(P37>0,Q37>0), 0, Q37) -> 0
B38: Exchange 11 | C38: =IF(AND(D38>0,E38>0), 0, D38) -> 0 | D38: 2 | E38: 2 | F38: =IF(AND(D38>0,E38>0), 0, E38) -> 0 | H38: Exchange 11 | I38: =IF(AND(J38>0,K38>0), 0, J38) -> 2 | J38: 2 | L38: =IF(AND(J38>0,K38>0), 0, K38) | N38: Exchange 11 | O38: =IF(AND(P38>0,Q38>0), 0, P38) | Q38: 2 | R38: =IF(AND(P38>0,Q38>0), 0, Q38) -> 2
